Workbook

Sheet ESCENARIO 1
A1: ESCENARIO 1 | B1: 01-feb | C1: 02-feb | D1: 03-feb | E1: 04-feb | F1: 05-feb | G1: 06-feb | H1: 07-feb | I1: 08-feb | J1: 09-feb | K1: 10-feb | L1: 11-feb | M1: 12-feb | N1: 13-feb | O1: 14-feb | P1: 15-feb | Q1: 16-feb | R1: 17-feb | S1: 18-feb | T1: 19-feb | U1: 20-feb | V1: 21-feb | W1: 22-feb | X1: 23-feb | Y1: 24-feb | Z1: 25-feb | AA1: 26-feb | AB1: 27-feb | AC1: 28-feb | AD1: 01-mar | AE1: 02-mar | AF1: 03-mar | AG1: 04-mar | AH1: 05-mar | AI1: 06-mar | AJ1: 07-mar | AK1: 08-mar | AL1: 09-mar | AM1: 10-mar | AN1: 11-mar | AO1: 12-mar | AP1: 13-mar | AQ1: 14-mar | AR1: 15-mar | AS1: 16-mar | AT1: 17-mar | AU1: 18-mar | AV1: 19-mar | AW1: 20-mar | AX1: 21-mar | AY1: 22-mar | AZ1: 23-mar | BA1: 24-mar | BB1: 25-mar | BC1: 26-mar | BD1: 27-mar | BE1: 28-mar | BF1: 29-mar | BG1: 30-mar | BH1: 31-mar | BI1: 01-abr | BJ1: 02-abr | BK1: 03-abr | BL1: 04-abr | BM1: 05-abr | BN1: 06-abr | BO1: 07-abr | BP1: 08-abr | BQ1: 09-abr | BR1: 10-abr | BS1: 11-abr | BT1: 12-abr | BU1: 13-abr | BV1: 14-abr | BW1: 15-abr | BX1: 16-abr | BY1: 17-abr | BZ1: 18-abr | CA1: 19-abr | CB1: 20-abr | CC1: 21-abr | CD1: 22-abr | CE1: 23-abr | CF1: 24-abr | CG1: 25-abr | CH1: 26-abr | CI1: 27-abr | CJ1: 28-abr | CK1: 29-abr | CL1: 30-abr | CM1: 01-may | CN1: 02-may | CO1: 03-may | CP1: 04-may | CQ1: 05-may | CR1: 06-may | CS1: 07-may | CT1: 08-may | CU1: 09-may | CV1: 10-may | CW1: 11-may | CX1: 12-may | CY1: 13-may | CZ1: 14-may | DA1: 15-may | DB1: 16-may | DC1: 17-may | DD1: 18-may | DE1: 19-may | DF1: 20-may | DG1: 21-may | DH1: 22-may | DI1: 23-may | DJ1: 24-may | DK1: 25-may | DL1: 26-may | DM1: 27-may | DN1: 28-may | DO1: 29-may | DP1: 30-may | DQ1: 31-may | DR1: 01-jun | DS1: 02-jun | DT1: 03-jun | DU1: 04-jun | DV1: 05-jun | DW1: 06-jun | DX1: 07-jun | DY1: 08-jun | DZ1: 09-jun | EA1: 10-jun | EB1: 11-jun | EC1: 12-jun | ED1: 13-jun | EE1: 14-jun | EF1: 15-jun | EG1: 16-jun | EH1: 17-jun | EI1: 18-jun | EJ1: 19-jun | EK1: 20-jun | EL1: 21-jun | EM1: 22-jun | EN1: 23-jun | EO1: 24-jun | EP1: 25-jun | EQ1: 26-jun | ER1: 27-jun | ES1: 28-jun | ET1: 29-jun | EU1: 30-jun | EV1: 01-jul | EW1: 02-jul | EX1: 03-jul | EY1: 04-jul | EZ1: 05-jul | FA1: 06-jul | FB1: 07-jul | FC1: 08-jul | FD1: 09-jul | FE1: 10-jul | FF1: 11-jul | FG1: 12-jul | FH1: 13-jul | FI1: 14-jul | FJ1: 15-jul | FK1: 16-jul | FL1: 17-jul | FM1: 18-jul | FN1: 19-jul | FO1: 20-jul | FP1: 21-jul | FQ1: 22-jul | FR1: 23-jul | FS1: 24-jul | FT1: 25-jul | FU1: 26-jul | FV1: 27-jul | FW1: 28-jul | FX1: 29-jul | FY1: 30-jul | FZ1: 31-jul | GA1: 01-ago | GB1: 02-ago | GC1: 03-ago | GD1: 04-ago | GE1: 05-ago | GF1: 06-ago | GG1: 07-ago | GH1: 08-ago | GI1: 09-ago | GJ1: 10-ago | GK1: 11-ago | GL1: 12-ago | GM1: 13-ago | GN1: 14-ago | GO1: 15-ago | GP1: 16-ago | GQ1: 17-ago | GR1: 18-ago | GS1: 19-ago | GT1: 20-ago | GU1: 21-ago | GV1: 22-ago | GW1: 23-ago | GX1: 24-ago | GY1: 25-ago | GZ1: 26-ago | HA1: 27-ago | HB1: 28-ago | HC1: 29-ago | HD1: 30-ago | HE1: 31-ago | HF1: 01-sep | HG1: 02-sep | HH1: 03-sep | HI1: 04-sep | HJ1: 05-sep | HK1: 06-sep | HL1: 07-sep | HM1: 08-sep | HN1: 09-sep | HO1: 10-sep | HP1: 11-sep | HQ1: 12-sep | HR1: 13-sep | HS1: 14-sep | HT1: 15-sep | HU1: 16-sep | HV1: 17-sep | HW1: 18-sep | HX1: 19-sep | HY1: 20-sep | HZ1: 21-sep | IA1: 22-sep | IB1: 23-sep | IC1: 24-sep | ID1: 25-sep | IE1: 26-sep | IF1: 27-sep | IG1: 28-sep | IH1: 29-sep | II1: 30-sep | IJ1: 01-oct | IK1: 02-oct | IL1: 03-oct | IM1: 04-oct | IN1: 05-oct | IO1: 06-oct | IP1: 07-oct | IQ1: 08-oct | IR1: 09-oct | IS1: 10-oct | IT1: 11-oct | IU1: 12-oct | IV1: 13-oct | IW1: 14-oct | IX1: 15-oct | IY1: 16-oct | IZ1: 17-oct | JA1: 18-oct | JB1: 19-oct | JC1: 20-oct | JD1: 21-oct | JE1: 22-oct | JF1: 23-oct | JG1: 24-oct | JH1: 25-oct | JI1: 26-oct | JJ1: 27-oct | JK1: 28-oct | JL1: 29-oct | JM1: 30-oct | JN1: 31-oct | JO1: 01-nov | JP1: 02-nov | JQ1: 03-nov | JR1: 04-nov | JS1: 05-nov | JT1: 06-nov | JU1: 07-nov | JV1: 08-nov | JW1: 09-nov | JX1: 10-nov | JY1: 11-nov | JZ1: 12-nov | KA1: 13-nov | KB1: 14-nov | KC1: 15-nov | KD1: 16-nov | KE1: 17-nov | KF1: 18-nov | KG1: 19-nov | KH1: 20-nov | KI1: 21-nov | KJ1: 22-nov | KK1: 23-nov | KL1: 24-nov | KM1: 25-nov | KN1: 26-nov | KO1: 27-nov | KP1: 28-nov | KQ1: 29-nov | KR1: 30-nov | KS1: 01-dic | KT1: 02-dic | KU1: 03-dic | KV1: 04-dic | KW1: 05-dic | KX1: 06-dic | KY1: 07-dic | KZ1: 08-dic | LA1: 09-dic | LB1: 10-dic | LC1: 11-dic | LD1: 12-dic | LE1: 13-dic | LF1: 14-dic | LG1: 15-dic | LH1: 16-dic | LI1: 17-dic | LJ1: 18-dic | LK1: 19-dic | LL1: 20-dic | LM1: 21-dic | LN1: 22-dic | LO1: 23-dic | LP1: 24-dic | LQ1: 25-dic | LR1: 26-dic | LS1: 27-dic | LT1: 28-dic | LU1: 29-dic | LV1: 30-dic | LW1: 31-dic | LX1: TOTAL
A2: CAJA INICIAL | B2: 2.376101e+09 | C2: =B4 -> 0 | D2: =C4 -> 6.3994528e+08 | E2: =D4+D9 -> 8.7380819e+08 | F2: =E4+E9 -> 4.9731141e+08 | G2: =F4+F9 -> 6.2814917e+08 | H2: =G4+G9 -> 8.1579303e+08 | I2: =H4+H9 -> 0 | J2: =I4+I9 -> 0 | K2: =J4+J9 -> 1.4233244e+09 | L2: =K4+K9 -> 7.2399112e+09 | ... AC2: =AB4+AB9 -> 5.6100402e+08 | AD2: 538000000 | AE2: =AD4+AD9 -> 0 | AF2: =AE4+AE9 -> 6.5203271e+08 | AG2: =AF4+AF9 -> 8.8995777e+08 | AH2: =AG4+AG9 -> 5.0670475e+08 | AI2: =AH4+AH9 -> 6.400138e+08 | AJ2: =AI4+AI9 -> 8.3120192e+08 | AK2: =AJ4+AJ9 -> 0 | AL2: =AK4+AK9 -> 0 | ... LW2: =LV4+LV9 -> 2.0280094e+09 | LX2: =SUM(ESCENARIO[[#This Row],[01-mar]:[31-dic]]) -> 4.0273471e+11
A3: GASTOS PROYECTADOS | B3: =SUMIFS(Gastos!$H:$H,Gastos!$I:$I,'ESCENARIO 1'!B$1) -> 0 | C3: =SUMIFS(Gastos!$H:$H,Gastos!$I:$I,'ESCENARIO 1'!C$1) -> 235000000 | D3: =SUMIFS(Gastos!$H:$H,Gastos!$I:$I,'ESCENARIO 1'!D$1) -> 1.4470035e+09 | E3: =SUMIFS(Gastos!$H:$H,Gastos!$I:$I,'ESCENARIO 1'!E$1) -> 0 | F3: =SUMIFS(Gastos!$H:$H,Gastos!$I:$I,'ESCENARIO 1'!F$1) -> 0 | G3: =SUMIFS(Gastos!$H:$H,Gastos!$I:$I,'ESCENARIO 1'!G$1) -> 0 | H3: =SUMIFS(Gastos!$H:$H,Gastos!$I:$I,'ESCENARIO 1'!H$1) -> 0 | I3: =SUMIFS(Gastos!$H:$H,Gastos!$I:$I,'ESCENARIO 1'!I$1) -> 0 | ... AC3: =SUMIFS(Gastos!$H:$H,Gastos!$I:$I,'ESCENARIO 1'!AC$1) -> 5.1450202e+08 | AD3: =SUMIFS(Gastos!$J:$J,Gastos!$K:$K,'ESCENARIO 1'!AD$1) -> 0 | AE3: =SUMIFS(Gastos!$J:$J,Gastos!$K:$K,'ESCENARIO 1'!AE$1) -> 0 | AF3: =SUMIFS(Gastos!$J:$J,Gastos!$K:$K,'ESCENARIO 1'!AF$1) -> 1107100000 | AG3: =SUMIFS(Gastos!$J:$J,Gastos!$K:$K,'ESCENARIO 1'!AG$1) -> 0 | AH3: =SUMIFS(Gastos!$J:$J,Gastos!$K:$K,'ESCENARIO 1'!AH$1) -> 0 | AI3: =SUMIFS(Gastos!$J:$J,Gastos!$K:$K,'ESCENARIO 1'!AI$1) -> 0 | AJ3: =SUMIFS(Gastos!$J:$J,Gastos!$K:$K,'ESCENARIO 1'!AJ$1) -> 0 | AK3: =SUMIFS(Gastos!$J:$J,Gastos!$K:$K,'ESCENARIO 1'!AK$1) -> 0 | ... BH3: =SUMIFS(Gastos!$J:$J,Gastos!$K:$K,'ESCENARIO 1'!BH$1) -> 2.0099429e+10 | BI3: =SUMIFS(Gastos!$L:$L,Gastos!$M:$M,'ESCENARIO 1'!BI$1) -> 0 | BJ3: =SUMIFS(Gastos!$L:$L,Gastos!$M:$M,'ESCENARIO 1'!BJ$1) -> 0 | BK3: =SUMIFS(Gastos!$L:$L,Gastos!$M:$M,'ESCENARIO 1'!BK$1) -> 0 | BL3: =SUMIFS(Gastos!$L:$L,Gastos!$M:$M,'ESCENARIO 1'!BL$1) -> 0 | BM3: =SUMIFS(Gastos!$L:$L,Gastos!$M:$M,'ESCENARIO 1'!BM$1) -> 0 | BN3: =SUMIFS(Gastos!$L:$L,Gastos!$M:$M,'ESCENARIO 1'!BN$1) -> 0 | BO3: =SUMIFS(Gastos!$L:$L,Gastos!$M:$M,'ESCENARIO 1'!BO$1) -> 1107100000 | BP3: =SUMIFS(Gastos!$L:$L,Gastos!$M:$M,'ESCENARIO 1'!BP$1) -> 0 | ... CL3: =SUMIFS(Gastos!$L:$L,Gastos!$M:$M,'ESCENARIO 1'!CL$1) -> 2.4010737e+10 | CM3: =SUMIFS(Gastos!$N:$N,Gastos!$O:$O,'ESCENARIO 1'!CM$1) -> 0 | CN3: =SUMIFS(Gastos!$N:$N,Gastos!$O:$O,'ESCENARIO 1'!CN$1) -> 0 | CO3: =SUMIFS(Gastos!$N:$N,Gastos!$O:$O,'ESCENARIO 1'!CO$1) -> 0 | CP3: =SUMIFS(Gastos!$N:$N,Gastos!$O:$O,'ESCENARIO 1'!CP$1) -> 0 | CQ3: =SUMIFS(Gastos!$N:$N,Gastos!$O:$O,'ESCENARIO 1'!CQ$1) -> 1107100000 | CR3: =SUMIFS(Gastos!$N:$N,Gastos!$O:$O,'ESCENARIO 1'!CR$1) -> 0 | CS3: =SUMIFS(Gastos!$N:$N,Gastos!$O:$O,'ESCENARIO 1'!CS$1) -> 0 | CT3: =SUMIFS(Gastos!$N:$N,Gastos!$O:$O,'ESCENARIO 1'!CT$1) -> 0 | ... DQ3: =SUMIFS(Gastos!$N:$N,Gastos!$O:$O,'ESCENARIO 1'!DQ$1) -> 0 | DR3: =SUMIFS(Gastos!$P:$P,Gastos!$Q:$Q,'ESCENARIO 1'!DR$1) -> 0 | DS3: =SUMIFS(Gastos!$P:$P,Gastos!$Q:$Q,'ESCENARIO 1'!DS$1) -> 1107100000 | DT3: =SUMIFS(Gastos!$P:$P,Gastos!$Q:$Q,'ESCENARIO 1'!DT$1) -> 0 | DU3: =SUMIFS(Gastos!$P:$P,Gastos!$Q:$Q,'ESCENARIO 1'!DU$1) -> 0 | DV3: =SUMIFS(Gastos!$P:$P,Gastos!$Q:$Q,'ESCENARIO 1'!DV$1) -> 0 | DW3: =SUMIFS(Gastos!$P:$P,Gastos!$Q:$Q,'ESCENARIO 1'!DW$1) -> 0 | DX3: =SUMIFS(Gastos!$P:$P,Gastos!$Q:$Q,'ESCENARIO 1'!DX$1) -> 0 | DY3: =SUMIFS(Gastos!$P:$P,Gastos!$Q:$Q,'ESCENARIO 1'!DY$1) -> 0 | ... EU3: =SUMIFS(Gastos!$P:$P,Gastos!$Q:$Q,'ESCENARIO 1'!EU$1) -> 2.8164597e+10 | EV3: =SUMIFS(Gastos!$R:$R,Gastos!$S:$S,'ESCENARIO 1'!EV$1) -> 0 | EW3: =SUMIFS(Gastos!$R:$R,Gastos!$S:$S,'ESCENARIO 1'!EW$1) -> 0 | EX3: =SUMIFS(Gastos!$R:$R,Gastos!$S:$S,'ESCENARIO 1'!EX$1) -> 0 | EY3: =SUMIFS(Gastos!$R:$R,Gastos!$S:$S,'ESCENARIO 1'!EY$1) -> 0 | EZ3: =SUMIFS(Gastos!$R:$R,Gastos!$S:$S,'ESCENARIO 1'!EZ$1) -> 0 | FA3: =SUMIFS(Gastos!$R:$R,Gastos!$S:$S,'ESCENARIO 1'!FA$1) -> 0 | FB3: =SUMIFS(Gastos!$R:$R,Gastos!$S:$S,'ESCENARIO 1'!FB$1) -> 1107100000 | FC3: =SUMIFS(Gastos!$R:$R,Gastos!$S:$S,'ESCENARIO 1'!FC$1) -> 0 | ... FZ3: =SUMIFS(Gastos!$R:$R,Gastos!$S:$S,'ESCENARIO 1'!FZ$1) -> 2.4685649e+10 | GA3: =SUMIFS(Gastos!$T:$T,Gastos!$U:$U,'ESCENARIO 1'!GA$1) -> 0 | GB3: =SUMIFS(Gastos!$T:$T,Gastos!$U:$U,'ESCENARIO 1'!GB$1) -> 0 | GC3: =SUMIFS(Gastos!$T:$T,Gastos!$U:$U,'ESCENARIO 1'!GC$1) -> 0 | GD3: =SUMIFS(Gastos!$T:$T,Gastos!$U:$U,'ESCENARIO 1'!GD$1) -> 1107100000 | GE3: =SUMIFS(Gastos!$T:$T,Gastos!$U:$U,'ESCENARIO 1'!GE$1) -> 0 | GF3: =SUMIFS(Gastos!$T:$T,Gastos!$U:$U,'ESCENARIO 1'!GF$1) -> 0 | GG3: =SUMIFS(Gastos!$T:$T,Gastos!$U:$U,'ESCENARIO 1'!GG$1) -> 0 | GH3: =SUMIFS(Gastos!$T:$T,Gastos!$U:$U,'ESCENARIO 1'!GH$1) -> 0 | ... HE3: =SUMIFS(Gastos!$T:$T,Gastos!$U:$U,'ESCENARIO 1'!HE$1) -> 2.1782913e+10 | HF3: =SUMIFS(Gastos!$V:$V,Gastos!$W:$W,'ESCENARIO 1'!HF$1) -> 1107100000 | HG3: =SUMIFS(Gastos!$V:$V,Gastos!$W:$W,'ESCENARIO 1'!HG$1) -> 0 | HH3: =SUMIFS(Gastos!$V:$V,Gastos!$W:$W,'ESCENARIO 1'!HH$1) -> 0 | HI3: =SUMIFS(Gastos!$V:$V,Gastos!$W:$W,'ESCENARIO 1'!HI$1) -> 0 | HJ3: =SUMIFS(Gastos!$V:$V,Gastos!$W:$W,'ESCENARIO 1'!HJ$1) -> 0 | HK3: =SUMIFS(Gastos!$V:$V,Gastos!$W:$W,'ESCENARIO 1'!HK$1) -> 0 | HL3: =SUMIFS(Gastos!$V:$V,Gastos!$W:$W,'ESCENARIO 1'!HL$1) -> 0 | HM3: =SUMIFS(Gastos!$V:$V,Gastos!$W:$W,'ESCENARIO 1'!HM$1) -> 1102000000 | ... II3: =SUMIFS(Gastos!$V:$V,Gastos!$W:$W,'ESCENARIO 1'!II$1) -> 2.116373e+10 | IJ3: =SUMIFS(Gastos!$X:$X,Gastos!$Y:$Y,'ESCENARIO 1'!IJ$1) -> 0 | IK3: =SUMIFS(Gastos!$X:$X,Gastos!$Y:$Y,'ESCENARIO 1'!IK$1) -> 0 | IL3: =SUMIFS(Gastos!$X:$X,Gastos!$Y:$Y,'ESCENARIO 1'!IL$1) -> 0 | IM3: =SUMIFS(Gastos!$X:$X,Gastos!$Y:$Y,'ESCENARIO 1'!IM$1) -> 0 | IN3: =SUMIFS(Gastos!$X:$X,Gastos!$Y:$Y,'ESCENARIO 1'!IN$1) -> 0 | IO3: =SUMIFS(Gastos!$X:$X,Gastos!$Y:$Y,'ESCENARIO 1'!IO$1) -> 1107100000 | IP3: =SUMIFS(Gastos!$X:$X,Gastos!$Y:$Y,'ESCENARIO 1'!IP$1) -> 0 | IQ3: =SUMIFS(Gastos!$X:$X,Gastos!$Y:$Y,'ESCENARIO 1'!IQ$1) -> 0 | ... JN3: =SUMIFS(Gastos!$X:$X,Gastos!$Y:$Y,'ESCENARIO 1'!JN$1) -> 0 | JO3: =SUMIFS(Gastos!$Z:$Z,Gastos!$AA:$AA,'ESCENARIO 1'!JO$1) -> 0 | JP3: =SUMIFS(Gastos!$Z:$Z,Gastos!$AA:$AA,'ESCENARIO 1'!JP$1) -> 0 | JQ3: =SUMIFS(Gastos!$Z:$Z,Gastos!$AA:$AA,'ESCENARIO 1'!JQ$1) -> 1107100000 | JR3: =SUMIFS(Gastos!$Z:$Z,Gastos!$AA:$AA,'ESCENARIO 1'!JR$1) -> 0 | JS3: =SUMIFS(Gastos!$Z:$Z,Gastos!$AA:$AA,'ESCENARIO 1'!JS$1) -> 0 | JT3: =SUMIFS(Gastos!$Z:$Z,Gastos!$AA:$AA,'ESCENARIO 1'!JT$1) -> 0 | JU3: =SUMIFS(Gastos!$Z:$Z,Gastos!$AA:$AA,'ESCENARIO 1'!JU$1) -> 0 | JV3: =SUMIFS(Gastos!$Z:$Z,Gastos!$AA:$AA,'ESCENARIO 1'!JV$1) -> 0 | ... KR3: =SUMIFS(Gastos!$Z:$Z,Gastos!$AA:$AA,'ESCENARIO 1'!KR$1) -> 2.0549133e+10 | KS3: =SUMIFS(Gastos!$AB:$AB,Gastos!$AC:$AC,'ESCENARIO 1'!KS$1) -> 1107100000 | KT3: =SUMIFS(Gastos!$AB:$AB,Gastos!$AC:$AC,'ESCENARIO 1'!KT$1) -> 0 | KU3: =SUMIFS(Gastos!$AB:$AB,Gastos!$AC:$AC,'ESCENARIO 1'!KU$1) -> 0 | KV3: =SUMIFS(Gastos!$AB:$AB,Gastos!$AC:$AC,'ESCENARIO 1'!KV$1) -> 0 | KW3: =SUMIFS(Gastos!$AB:$AB,Gastos!$AC:$AC,'ESCENARIO 1'!KW$1) -> 0 | KX3: =SUMIFS(Gastos!$AB:$AB,Gastos!$AC:$AC,'ESCENARIO 1'!KX$1) -> 0 | KY3: =SUMIFS(Gastos!$AB:$AB,Gastos!$AC:$AC,'ESCENARIO 1'!KY$1) -> 0 | KZ3: =SUMIFS(Gastos!$AB:$AB,Gastos!$AC:$AC,'ESCENARIO 1'!KZ$1) -> 0 | ... LW3: =SUMIFS(Gastos!$AB:$AB,Gastos!$AC:$AC,'ESCENARIO 1'!LW$1) -> 0 | LX3: =SUM(ESCENARIO[[#This Row],[01-mar]:[31-dic]]) -> 3.4402217e+11
A4: INGRESOS FINANCIEROS PROYECTADOS | B4: =SUMIFS('INGRESOSXDIA-HABIL'!$D:$D,'INGRESOSXDIA-HABIL'!$C:$C,ESCENARIO[[#Headers],[01-feb]]) -> 0 | C4: =SUMIFS('INGRESOSXDIA-HABIL'!$D:$D,'INGRESOSXDIA-HABIL'!$C:$C,ESCENARIO[[#Headers],[02-feb]]) -> 6.3994528e+08 | D4: =SUMIFS('INGRESOSXDIA-HABIL'!$D:$D,'INGRESOSXDIA-HABIL'!$C:$C,ESCENARIO[[#Headers],[03-feb]]) -> 8.7302777e+08 | E4: =SUMIFS('INGRESOSXDIA-HABIL'!$D:$D,'INGRESOSXDIA-HABIL'!$C:$C,ESCENARIO[[#Headers],[04-feb]]) -> 4.9731141e+08 | F4: =SUMIFS('INGRESOSXDIA-HABIL'!$D:$D,'INGRESOSXDIA-HABIL'!$C:$C,ESCENARIO[[#Headers],[05-feb]]) -> 6.2814917e+08 | G4: =SUMIFS('INGRESOSXDIA-HABIL'!$D:$D,'INGRESOSXDIA-HABIL'!$C:$C,ESCENARIO[[#Headers],[06-feb]]) -> 8.1579303e+08 | H4: =SUMIFS('INGRESOSXDIA-HABIL'!$D:$D,'INGRESOSXDIA-HABIL'!$C:$C,ESCENARIO[[#Headers],[07-feb]]) -> 0 | I4: =SUMIFS('INGRESOSXDIA-HABIL'!$D:$D,'INGRESOSXDIA-HABIL'!$C:$C,ESCENARIO[[#Headers],[08-feb]]) -> 0 | J4: =SUMIFS('INGRESOSXDIA-HABIL'!$D:$D,'INGRESOSXDIA-HABIL'!$C:$C,ESCENARIO[[#Headers],[09-feb]]) -> 1.4233244e+09 | K4: =SUMIFS('INGRESOSXDIA-HABIL'!$D:$D,'INGRESOSXDIA-HABIL'!$C:$C,ESCENARIO[[#Headers],[10-feb]]) -> 7.2399112e+09 | L4: =SUMIFS('INGRESOSXDIA-HABIL'!$D:$D,'INGRESOSXDIA-HABIL'!$C:$C,ESCENARIO[[#Headers],[11-feb]]) -> 1.4022844e+09 | M4: =SUMIFS('INGRESOSXDIA-HABIL'!$D:$D,'INGRESOSXDIA-HABIL'!$C:$C,ESCENARIO[[#Headers],[12-feb]]) -> 9.4060295e+08 | N4: =SUMIFS('INGRESOSXDIA-HABIL'!$D:$D,'INGRESOSXDIA-HABIL'!$C:$C,ESCENARIO[[#Headers],[13-feb]]) -> 2.6451394e+09 | O4: =SUMIFS('INGRESOSXDIA-HABIL'!$D:$D,'INGRESOSXDIA-HABIL'!$C:$C,ESCENARIO[[#Headers],[14-feb]]) -> 0 | P4: =SUMIFS('INGRESOSXDIA-HABIL'!$D:$D,'INGRESOSXDIA-HABIL'!$C:$C,ESCENARIO[[#Headers],[15-feb]]) -> 0 | Q4: =SUMIFS('INGRESOSXDIA-HABIL'!$D:$D,'INGRESOSXDIA-HABIL'!$C:$C,ESCENARIO[[#Headers],[16-feb]]) -> 2.4180253e+09 | R4: =SUMIFS('INGRESOSXDIA-HABIL'!$D:$D,'INGRESOSXDIA-HABIL'!$C:$C,ESCENARIO[[#Headers],[17-feb]]) -> 1.2890997e+09 | S4: =SUMIFS('INGRESOSXDIA-HABIL'!$D:$D,'INGRESOSXDIA-HABIL'!$C:$C,ESCENARIO[[#Headers],[18-feb]]) -> 1.5886214e+09 | T4: =SUMIFS('INGRESOSXDIA-HABIL'!$D:$D,'INGRESOSXDIA-HABIL'!$C:$C,ESCENARIO[[#Headers],[19-feb]]) -> 2.5939073e+09 | U4: =SUMIFS('INGRESOSXDIA-HABIL'!$D:$D,'INGRESOSXDIA-HABIL'!$C:$C,ESCENARIO[[#Headers],[20-feb]]) -> 2.6878119e+09 | V4: =SUMIFS('INGRESOSXDIA-HABIL'!$D:$D,'INGRESOSXDIA-HABIL'!$C:$C,ESCENARIO[[#Headers],[21-feb]]) -> 0 | W4: =SUMIFS('INGRESOSXDIA-HABIL'!$D:$D,'INGRESOSXDIA-HABIL'!$C:$C,ESCENARIO[[#Headers],[22-feb]]) -> 0 | X4: =SUMIFS('INGRESOSXDIA-HABIL'!$D:$D,'INGRESOSXDIA-HABIL'!$C:$C,ESCENARIO[[#Headers],[23-feb]]) -> 1.5125643e+09 | Y4: =SUMIFS('INGRESOSXDIA-HABIL'!$D:$D,'INGRESOSXDIA-HABIL'!$C:$C,ESCENARIO[[#Headers],[24-feb]]) -> 2.8732619e+09 | Z4: =SUMIFS('INGRESOSXDIA-HABIL'!$D:$D,'INGRESOSXDIA-HABIL'!$C:$C,ESCENARIO[[#Headers],[25-feb]]) -> 1.1742255e+09 | AA4: =SUMIFS('INGRESOSXDIA-HABIL'!$D:$D,'INGRESOSXDIA-HABIL'!$C:$C,ESCENARIO[[#Headers],[26-feb]]) -> 1.6219583e+09 | AB4: =SUMIFS('INGRESOSXDIA-HABIL'!$D:$D,'INGRESOSXDIA-HABIL'!$C:$C,ESCENARIO[[#Headers],[27-feb]]) -> 5.4434981e+08 | AC4: =SUMIFS('INGRESOSXDIA-HABIL'!$D:$D,'INGRESOSXDIA-HABIL'!$C:$C,ESCENARIO[[#Headers],[28-feb]]) -> 1.0930054e+09 | AD4: =SUMIFS('INGRESOSXDIA-HABIL'!$F$4:$F$25,'INGRESOSXDIA-HABIL'!$E$4:$E$25,ESCENARIO[[#Headers],[01-mar]]) -> 0 | AE4: =SUMIFS('INGRESOSXDIA-HABIL'!$F$4:$F$25,'INGRESOSXDIA-HABIL'!$E$4:$E$25,ESCENARIO[[#Headers],[02-mar]]) -> 6.5203271e+08 | AF4: =SUMIFS('INGRESOSXDIA-HABIL'!$F$4:$F$25,'INGRESOSXDIA-HABIL'!$E$4:$E$25,ESCENARIO[[#Headers],[03-mar]]) -> 8.8951772e+08 | AG4: =SUMIFS('INGRESOSXDIA-HABIL'!$F$4:$F$25,'INGRESOSXDIA-HABIL'!$E$4:$E$25,ESCENARIO[[#Headers],[04-mar]]) -> 5.0670475e+08 | AH4: =SUMIFS('INGRESOSXDIA-HABIL'!$F$4:$F$25,'INGRESOSXDIA-HABIL'!$E$4:$E$25,ESCENARIO[[#Headers],[05-mar]]) -> 6.400138e+08 | AI4: =SUMIFS('INGRESOSXDIA-HABIL'!$F$4:$F$25,'INGRESOSXDIA-HABIL'!$E$4:$E$25,ESCENARIO[[#Headers],[06-mar]]) -> 8.3120192e+08 | AJ4: =SUMIFS('INGRESOSXDIA-HABIL'!$F$4:$F$25,'INGRESOSXDIA-HABIL'!$E$4:$E$25,ESCENARIO[[#Headers],[07-mar]]) -> 0 | AK4: =SUMIFS('INGRESOSXDIA-HABIL'!$F$4:$F$25,'INGRESOSXDIA-HABIL'!$E$4:$E$25,ESCENARIO[[#Headers],[08-mar]]) -> 0 | AL4: =SUMIFS('INGRESOSXDIA-HABIL'!$F$4:$F$25,'INGRESOSXDIA-HABIL'!$E$4:$E$25,ESCENARIO[[#Headers],[09-mar]]) -> 1.4502085e+09 | AM4: =SUMIFS('INGRESOSXDIA-HABIL'!$F$4:$F$25,'INGRESOSXDIA-HABIL'!$E$4:$E$25,ESCENARIO[[#Headers],[10-mar]]) -> 7.3766604e+09 | AN4: =SUMIFS('INGRESOSXDIA-HABIL'!$F$4:$F$25,'INGRESOSXDIA-HABIL'!$E$4:$E$25,ESCENARIO[[#Headers],[11-mar]]) -> 1.428771e+09 | AO4: =SUMIFS('INGRESOSXDIA-HABIL'!$F$4:$F$25,'INGRESOSXDIA-HABIL'!$E$4:$E$25,ESCENARIO[[#Headers],[12-mar]]) -> 9.5836928e+08 | AP4: =SUMIFS('INGRESOSXDIA-HABIL'!$F$4:$F$25,'INGRESOSXDIA-HABIL'!$E$4:$E$25,ESCENARIO[[#Headers],[13-mar]]) -> 2.6951014e+09 | AQ4: =SUMIFS('INGRESOSXDIA-HABIL'!$F$4:$F$25,'INGRESOSXDIA-HABIL'!$E$4:$E$25,ESCENARIO[[#Headers],[14-mar]]) -> 0 | AR4: =SUMIFS('INGRESOSXDIA-HABIL'!$F$4:$F$25,'INGRESOSXDIA-HABIL'!$E$4:$E$25,ESCENARIO[[#Headers],[15-mar]]) -> 0 | AS4: =SUMIFS('INGRESOSXDIA-HABIL'!$F$4:$F$25,'INGRESOSXDIA-HABIL'!$E$4:$E$25,ESCENARIO[[#Headers],[16-mar]]) -> 2.4636976e+09 | AT4: =SUMIFS('INGRESOSXDIA-HABIL'!$F$4:$F$25,'INGRESOSXDIA-HABIL'!$E$4:$E$25,ESCENARIO[[#Headers],[17-mar]]) -> 1.3134485e+09 | AU4: =SUMIFS('INGRESOSXDIA-HABIL'!$F$4:$F$25,'INGRESOSXDIA-HABIL'!$E$4:$E$25,ESCENARIO[[#Headers],[18-mar]]) -> 1.6186277e+09 | AV4: =SUMIFS('INGRESOSXDIA-HABIL'!$F$4:$F$25,'INGRESOSXDIA-HABIL'!$E$4:$E$25,ESCENARIO[[#Headers],[19-mar]]) -> 2.6429016e+09 | AW4: =SUMIFS('INGRESOSXDIA-HABIL'!$F$4:$F$25,'INGRESOSXDIA-HABIL'!$E$4:$E$25,ESCENARIO[[#Headers],[20-mar]]) -> 2.7385799e+09 | AX4: =SUMIFS('INGRESOSXDIA-HABIL'!$F$4:$F$25,'INGRESOSXDIA-HABIL'!$E$4:$E$25,ESCENARIO[[#Headers],[21-mar]]) -> 1.5411339e+09 | AY4: =SUMIFS('INGRESOSXDIA-HABIL'!$F$4:$F$25,'INGRESOSXDIA-HABIL'!$E$4:$E$25,ESCENARIO[[#Headers],[22-mar]]) -> 2.9275327e+09 | AZ4: =SUMIFS('INGRESOSXDIA-HABIL'!$F$4:$F$25,'INGRESOSXDIA-HABIL'!$E$4:$E$25,ESCENARIO[[#Headers],[23-mar]]) -> 0 | BA4: =SUMIFS('INGRESOSXDIA-HABIL'!$F$4:$F$25,'INGRESOSXDIA-HABIL'!$E$4:$E$25,ESCENARIO[[#Headers],[24-mar]]) -> 0 | BB4: =SUMIFS('INGRESOSXDIA-HABIL'!$F$4:$F$25,'INGRESOSXDIA-HABIL'!$E$4:$E$25,ESCENARIO[[#Headers],[25-mar]]) -> 1.1964045e+09 | BC4: =SUMIFS('INGRESOSXDIA-HABIL'!$F$4:$F$25,'INGRESOSXDIA-HABIL'!$E$4:$E$25,ESCENARIO[[#Headers],[26-mar]]) -> 1.6525942e+09 | BD4: =SUMIFS('INGRESOSXDIA-HABIL'!$F$4:$F$25,'INGRESOSXDIA-HABIL'!$E$4:$E$25,ESCENARIO[[#Headers],[27-mar]]) -> 5.5463161e+08 | BE4: =SUMIFS('INGRESOSXDIA-HABIL'!$F$4:$F$25,'INGRESOSXDIA-HABIL'!$E$4:$E$25,ESCENARIO[[#Headers],[28-mar]]) -> 0 | BF4: =SUMIFS('INGRESOSXDIA-HABIL'!$F$4:$F$25,'INGRESOSXDIA-HABIL'!$E$4:$E$25,ESCENARIO[[#Headers],[29-mar]]) -> 0 | BG4: =SUMIFS('INGRESOSXDIA-HABIL'!$F$4:$F$25,'INGRESOSXDIA-HABIL'!$E$4:$E$25,ESCENARIO[[#Headers],[30-mar]]) -> 1.1136504e+09 | BH4: =SUMIFS('INGRESOSXDIA-HABIL'!$F$4:$F$25,'INGRESOSXDIA-HABIL'!$E$4:$E$25,ESCENARIO[[#Headers],[31-mar]]) -> 0 | BI4: =SUMIFS('INGRESOSXDIA-HABIL'!$H$4:$H$25,'INGRESOSXDIA-HABIL'!$G$4:$G$25,ESCENARIO[[#Headers],[01-abr]]) -> 6.6195686e+08 | BJ4: =SUMIFS('INGRESOSXDIA-HABIL'!$H$4:$H$25,'INGRESOSXDIA-HABIL'!$G$4:$G$25,ESCENARIO[[#Headers],[02-abr]]) -> 0 | BK4: =SUMIFS('INGRESOSXDIA-HABIL'!$H$4:$H$25,'INGRESOSXDIA-HABIL'!$G$4:$G$25,ESCENARIO[[#Headers],[03-abr]]) -> 0 | BL4: =SUMIFS('INGRESOSXDIA-HABIL'!$H$4:$H$25,'INGRESOSXDIA-HABIL'!$G$4:$G$25,ESCENARIO[[#Headers],[04-abr]]) -> 0 | BM4: =SUMIFS('INGRESOSXDIA-HABIL'!$H$4:$H$25,'INGRESOSXDIA-HABIL'!$G$4:$G$25,ESCENARIO[[#Headers],[05-abr]]) -> 0 | BN4: =SUMIFS('INGRESOSXDIA-HABIL'!$H$4:$H$25,'INGRESOSXDIA-HABIL'!$G$4:$G$25,ESCENARIO[[#Headers],[06-abr]]) -> 9.0305647e+08 | BO4: =SUMIFS('INGRESOSXDIA-HABIL'!$H$4:$H$25,'INGRESOSXDIA-HABIL'!$G$4:$G$25,ESCENARIO[[#Headers],[07-abr]]) -> 5.1441696e+08 | BP4: =SUMIFS('INGRESOSXDIA-HABIL'!$H$4:$H$25,'INGRESOSXDIA-HABIL'!$G$4:$G$25,ESCENARIO[[#Headers],[08-abr]]) -> 6.4975502e+08 | BQ4: =SUMIFS('INGRESOSXDIA-HABIL'!$H$4:$H$25,'INGRESOSXDIA-HABIL'!$G$4:$G$25,ESCENARIO[[#Headers],[09-abr]]) -> 8.4385308e+08 | BR4: =SUMIFS('INGRESOSXDIA-HABIL'!$H$4:$H$25,'INGRESOSXDIA-HABIL'!$G$4:$G$25,ESCENARIO[[#Headers],[10-abr]]) -> 1.4722811e+09 | BS4: =SUMIFS('INGRESOSXDIA-HABIL'!$H$4:$H$25,'INGRESOSXDIA-HABIL'!$G$4:$G$25,ESCENARIO[[#Headers],[11-abr]]) -> 0 | BT4: =SUMIFS('INGRESOSXDIA-HABIL'!$H$4:$H$25,'INGRESOSXDIA-HABIL'!$G$4:$G$25,ESCENARIO[[#Headers],[12-abr]]) -> 0 | BU4: =SUMIFS('INGRESOSXDIA-HABIL'!$H$4:$H$25,'INGRESOSXDIA-HABIL'!$G$4:$G$25,ESCENARIO[[#Headers],[13-abr]]) -> 7.4889355e+09 | BV4: =SUMIFS('INGRESOSXDIA-HABIL'!$H$4:$H$25,'INGRESOSXDIA-HABIL'!$G$4:$G$25,ESCENARIO[[#Headers],[14-abr]]) -> 1.4505174e+09 | BW4: =SUMIFS('INGRESOSXDIA-HABIL'!$H$4:$H$25,'INGRESOSXDIA-HABIL'!$G$4:$G$25,ESCENARIO[[#Headers],[15-abr]]) -> 9.7295596e+08 | BX4: =SUMIFS('INGRESOSXDIA-HABIL'!$H$4:$H$25,'INGRESOSXDIA-HABIL'!$G$4:$G$25,ESCENARIO[[#Headers],[16-abr]]) -> 2.7361217e+09 | BY4: =SUMIFS('INGRESOSXDIA-HABIL'!$H$4:$H$25,'INGRESOSXDIA-HABIL'!$G$4:$G$25,ESCENARIO[[#Headers],[17-abr]]) -> 2.5011958e+09 | BZ4: =SUMIFS('INGRESOSXDIA-HABIL'!$H$4:$H$25,'INGRESOSXDIA-HABIL'!$G$4:$G$25,ESCENARIO[[#Headers],[18-abr]]) -> 0 | CA4: =SUMIFS('INGRESOSXDIA-HABIL'!$H$4:$H$25,'INGRESOSXDIA-HABIL'!$G$4:$G$25,ESCENARIO[[#Headers],[19-abr]]) -> 0 | CB4: =SUMIFS('INGRESOSXDIA-HABIL'!$H$4:$H$25,'INGRESOSXDIA-HABIL'!$G$4:$G$25,ESCENARIO[[#Headers],[20-abr]]) -> 1.3334396e+09 | CC4: =SUMIFS('INGRESOSXDIA-HABIL'!$H$4:$H$25,'INGRESOSXDIA-HABIL'!$G$4:$G$25,ESCENARIO[[#Headers],[21-abr]]) -> 1.6432637e+09 | CD4: =SUMIFS('INGRESOSXDIA-HABIL'!$H$4:$H$25,'INGRESOSXDIA-HABIL'!$G$4:$G$25,ESCENARIO[[#Headers],[22-abr]]) -> 2.6831274e+09 | CE4: =SUMIFS('INGRESOSXDIA-HABIL'!$H$4:$H$25,'INGRESOSXDIA-HABIL'!$G$4:$G$25,ESCENARIO[[#Headers],[23-abr]]) -> 2.7802619e+09 | CF4: =SUMIFS('INGRESOSXDIA-HABIL'!$H$4:$H$25,'INGRESOSXDIA-HABIL'!$G$4:$G$25,ESCENARIO[[#Headers],[24-abr]]) -> 1.5645905e+09 | CG4: =SUMIFS('INGRESOSXDIA-HABIL'!$H$4:$H$25,'INGRESOSXDIA-HABIL'!$G$4:$G$25,ESCENARIO[[#Headers],[25-abr]]) -> 0 | CH4: =SUMIFS('INGRESOSXDIA-HABIL'!$H$4:$H$25,'INGRESOSXDIA-HABIL'!$G$4:$G$25,ESCENARIO[[#Headers],[26-abr]]) -> 0 | CI4: =SUMIFS('INGRESOSXDIA-HABIL'!$H$4:$H$25,'INGRESOSXDIA-HABIL'!$G$4:$G$25,ESCENARIO[[#Headers],[27-abr]]) -> 2.9720907e+09 | CJ4: =SUMIFS('INGRESOSXDIA-HABIL'!$H$4:$H$25,'INGRESOSXDIA-HABIL'!$G$4:$G$25,ESCENARIO[[#Headers],[28-abr]]) -> 1.2146142e+09 | CK4: =SUMIFS('INGRESOSXDIA-HABIL'!$H$4:$H$25,'INGRESOSXDIA-HABIL'!$G$4:$G$25,ESCENARIO[[#Headers],[29-abr]]) -> 1.6777472e+09 | CL4: =SUMIFS('INGRESOSXDIA-HABIL'!$H$4:$H$25,'INGRESOSXDIA-HABIL'!$G$4:$G$25,ESCENARIO[[#Headers],[30-abr]]) -> 1.6936738e+09 | CM4: =SUMIFS('INGRESOSXDIA-HABIL'!$J$4:$J$25,'INGRESOSXDIA-HABIL'!$I$4:$I$25,ESCENARIO[[#Headers],[01-may]]) -> 0 | CN4: =SUMIFS('INGRESOSXDIA-HABIL'!$J$4:$J$25,'INGRESOSXDIA-HABIL'!$I$4:$I$25,ESCENARIO[[#Headers],[02-may]]) -> 0 | CO4: =SUMIFS('INGRESOSXDIA-HABIL'!$J$4:$J$25,'INGRESOSXDIA-HABIL'!$I$4:$I$25,ESCENARIO[[#Headers],[03-may]]) -> 0 | CP4: =SUMIFS('INGRESOSXDIA-HABIL'!$J$4:$J$25,'INGRESOSXDIA-HABIL'!$I$4:$I$25,ESCENARIO[[#Headers],[04-may]]) -> 7.0108957e+08 | CQ4: =SUMIFS('INGRESOSXDIA-HABIL'!$J$4:$J$25,'INGRESOSXDIA-HABIL'!$I$4:$I$25,ESCENARIO[[#Headers],[05-may]]) -> 9.5644219e+08 | CR4: =SUMIFS('INGRESOSXDIA-HABIL'!$J$4:$J$25,'INGRESOSXDIA-HABIL'!$I$4:$I$25,ESCENARIO[[#Headers],[06-may]]) -> 5.4482759e+08 | CS4: =SUMIFS('INGRESOSXDIA-HABIL'!$J$4:$J$25,'INGRESOSXDIA-HABIL'!$I$4:$I$25,ESCENARIO[[#Headers],[07-may]]) -> 6.8816639e+08 | CT4: =SUMIFS('INGRESOSXDIA-HABIL'!$J$4:$J$25,'INGRESOSXDIA-HABIL'!$I$4:$I$25,ESCENARIO[[#Headers],[08-may]]) -> 8.9373889e+08 | CU4: =SUMIFS('INGRESOSXDIA-HABIL'!$J$4:$J$25,'INGRESOSXDIA-HABIL'!$I$4:$I$25,ESCENARIO[[#Headers],[09-may]]) -> 0 | CV4: =SUMIFS('INGRESOSXDIA-HABIL'!$J$4:$J$25,'INGRESOSXDIA-HABIL'!$I$4:$I$25,ESCENARIO[[#Headers],[10-may]]) -> 0 | CW4: =SUMIFS('INGRESOSXDIA-HABIL'!$J$4:$J$25,'INGRESOSXDIA-HABIL'!$I$4:$I$25,ESCENARIO[[#Headers],[11-may]]) -> 1.5593175e+09 | CX4: =SUMIFS('INGRESOSXDIA-HABIL'!$J$4:$J$25,'INGRESOSXDIA-HABIL'!$I$4:$I$25,ESCENARIO[[#Headers],[12-may]]) -> 7.9316567e+09 | CY4: =SUMIFS('INGRESOSXDIA-HABIL'!$J$4:$J$25,'INGRESOSXDIA-HABIL'!$I$4:$I$25,ESCENARIO[[#Headers],[13-may]]) -> 1.5362672e+09 | CZ4: =SUMIFS('INGRESOSXDIA-HABIL'!$J$4:$J$25,'INGRESOSXDIA-HABIL'!$I$4:$I$25,ESCENARIO[[#Headers],[14-may]]) -> 1.0304739e+09 | DA4: =SUMIFS('INGRESOSXDIA-HABIL'!$J$4:$J$25,'INGRESOSXDIA-HABIL'!$I$4:$I$25,ESCENARIO[[#Headers],[15-may]]) -> 2.8978722e+09 | DB4: =SUMIFS('INGRESOSXDIA-HABIL'!$J$4:$J$25,'INGRESOSXDIA-HABIL'!$I$4:$I$25,ESCENARIO[[#Headers],[16-may]]) -> 0 | DC4: =SUMIFS('INGRESOSXDIA-HABIL'!$J$4:$J$25,'INGRESOSXDIA-HABIL'!$I$4:$I$25,ESCENARIO[[#Headers],[17-may]]) -> 0 | DD4: =SUMIFS('INGRESOSXDIA-HABIL'!$J$4:$J$25,'INGRESOSXDIA-HABIL'!$I$4:$I$25,ESCENARIO[[#Headers],[18-may]]) -> 2.6490583e+09 | DE4: =SUMIFS('INGRESOSXDIA-HABIL'!$J$4:$J$25,'INGRESOSXDIA-HABIL'!$I$4:$I$25,ESCENARIO[[#Headers],[19-may]]) -> 1.4122682e+09 | DF4: =SUMIFS('INGRESOSXDIA-HABIL'!$J$4:$J$25,'INGRESOSXDIA-HABIL'!$I$4:$I$25,ESCENARIO[[#Headers],[20-may]]) -> 1.740408e+09 | DG4: =SUMIFS('INGRESOSXDIA-HABIL'!$J$4:$J$25,'INGRESOSXDIA-HABIL'!$I$4:$I$25,ESCENARIO[[#Headers],[21-may]]) -> 2.8417451e+09 | DH4: =SUMIFS('INGRESOSXDIA-HABIL'!$J$4:$J$25,'INGRESOSXDIA-HABIL'!$I$4:$I$25,ESCENARIO[[#Headers],[22-may]]) -> 2.9446219e+09 | DI4: =SUMIFS('INGRESOSXDIA-HABIL'!$J$4:$J$25,'INGRESOSXDIA-HABIL'!$I$4:$I$25,ESCENARIO[[#Headers],[23-may]]) -> 0 | DJ4: =SUMIFS('INGRESOSXDIA-HABIL'!$J$4:$J$25,'INGRESOSXDIA-HABIL'!$I$4:$I$25,ESCENARIO[[#Headers],[24-may]]) -> 0 | DK4: =SUMIFS('INGRESOSXDIA-HABIL'!$J$4:$J$25,'INGRESOSXDIA-HABIL'!$I$4:$I$25,ESCENARIO[[#Headers],[25-may]]) -> 0 | DL4: =SUMIFS('INGRESOSXDIA-HABIL'!$J$4:$J$25,'INGRESOSXDIA-HABIL'!$I$4:$I$25,ESCENARIO[[#Headers],[26-may]]) -> 1.6570839e+09 | DM4: =SUMIFS('INGRESOSXDIA-HABIL'!$J$4:$J$25,'INGRESOSXDIA-HABIL'!$I$4:$I$25,ESCENARIO[[#Headers],[27-may]]) -> 3.1477909e+09 | DN4: =SUMIFS('INGRESOSXDIA-HABIL'!$J$4:$J$25,'INGRESOSXDIA-HABIL'!$I$4:$I$25,ESCENARIO[[#Headers],[28-may]]) -> 1.2864182e+09 | DO4: =SUMIFS('INGRESOSXDIA-HABIL'!$J$4:$J$25,'INGRESOSXDIA-HABIL'!$I$4:$I$25,ESCENARIO[[#Headers],[29-may]]) -> 1.7769301e+09 | DP4: =SUMIFS('INGRESOSXDIA-HABIL'!$J$4:$J$25,'INGRESOSXDIA-HABIL'!$I$4:$I$25,ESCENARIO[[#Headers],[30-may]]) -> 5.9636032e+08 | DQ4: =SUMIFS('INGRESOSXDIA-HABIL'!$J$4:$J$25,'INGRESOSXDIA-HABIL'!$I$4:$I$25,ESCENARIO[[#Headers],[31-may]]) -> 1.1974379e+09 | DR4: =SUMIFS('INGRESOSXDIA-HABIL'!$L$4:$L$25,'INGRESOSXDIA-HABIL'!$K$4:$K$25,ESCENARIO[[#Headers],[01-jun]]) -> 0 | DS4: =SUMIFS('INGRESOSXDIA-HABIL'!$L$4:$L$25,'INGRESOSXDIA-HABIL'!$K$4:$K$25,ESCENARIO[[#Headers],[02-jun]]) -> 6.8187852e+08 | DT4: =SUMIFS('INGRESOSXDIA-HABIL'!$L$4:$L$25,'INGRESOSXDIA-HABIL'!$K$4:$K$25,ESCENARIO[[#Headers],[03-jun]]) -> 9.3023404e+08 | DU4: =SUMIFS('INGRESOSXDIA-HABIL'!$L$4:$L$25,'INGRESOSXDIA-HABIL'!$K$4:$K$25,ESCENARIO[[#Headers],[04-jun]]) -> 5.2989838e+08 | DV4: =SUMIFS('INGRESOSXDIA-HABIL'!$L$4:$L$25,'INGRESOSXDIA-HABIL'!$K$4:$K$25,ESCENARIO[[#Headers],[05-jun]]) -> 6.6930945e+08 | DW4: =SUMIFS('INGRESOSXDIA-HABIL'!$L$4:$L$25,'INGRESOSXDIA-HABIL'!$K$4:$K$25,ESCENARIO[[#Headers],[06-jun]]) -> 0 | DX4: =SUMIFS('INGRESOSXDIA-HABIL'!$L$4:$L$25,'INGRESOSXDIA-HABIL'!$K$4:$K$25,ESCENARIO[[#Headers],[07-jun]]) -> 0 | DY4: =SUMIFS('INGRESOSXDIA-HABIL'!$L$4:$L$25,'INGRESOSXDIA-HABIL'!$K$4:$K$25,ESCENARIO[[#Headers],[08-jun]]) -> 8.6924891e+08 | DZ4: =SUMIFS('INGRESOSXDIA-HABIL'!$L$4:$L$25,'INGRESOSXDIA-HABIL'!$K$4:$K$25,ESCENARIO[[#Headers],[09-jun]]) -> 1.5165895e+09 | EA4: =SUMIFS('INGRESOSXDIA-HABIL'!$L$4:$L$25,'INGRESOSXDIA-HABIL'!$K$4:$K$25,ESCENARIO[[#Headers],[10-jun]]) -> 7.7143157e+09 | EB4: =SUMIFS('INGRESOSXDIA-HABIL'!$L$4:$L$25,'INGRESOSXDIA-HABIL'!$K$4:$K$25,ESCENARIO[[#Headers],[11-jun]]) -> 1.4941709e+09 | EC4: =SUMIFS('INGRESOSXDIA-HABIL'!$L$4:$L$25,'INGRESOSXDIA-HABIL'!$K$4:$K$25,ESCENARIO[[#Headers],[12-jun]]) -> 1.0022372e+09 | ED4: =SUMIFS('INGRESOSXDIA-HABIL'!$L$4:$L$25,'INGRESOSXDIA-HABIL'!$K$4:$K$25,ESCENARIO[[#Headers],[13-jun]]) -> 0 | EE4: =SUMIFS('INGRESOSXDIA-HABIL'!$L$4:$L$25,'INGRESOSXDIA-HABIL'!$K$4:$K$25,ESCENARIO[[#Headers],[14-jun]]) -> 0 | EF4: =SUMIFS('INGRESOSXDIA-HABIL'!$L$4:$L$25,'INGRESOSXDIA-HABIL'!$K$4:$K$25,ESCENARIO[[#Headers],[15-jun]]) -> 0 | EG4: =SUMIFS('INGRESOSXDIA-HABIL'!$L$4:$L$25,'INGRESOSXDIA-HABIL'!$K$4:$K$25,ESCENARIO[[#Headers],[16-jun]]) -> 2.8184655e+09 | EH4: =SUMIFS('INGRESOSXDIA-HABIL'!$L$4:$L$25,'INGRESOSXDIA-HABIL'!$K$4:$K$25,ESCENARIO[[#Headers],[17-jun]]) -> 2.5764696e+09 | EI4: =SUMIFS('INGRESOSXDIA-HABIL'!$L$4:$L$25,'INGRESOSXDIA-HABIL'!$K$4:$K$25,ESCENARIO[[#Headers],[18-jun]]) -> 1.3735696e+09 | EJ4: =SUMIFS('INGRESOSXDIA-HABIL'!$L$4:$L$25,'INGRESOSXDIA-HABIL'!$K$4:$K$25,ESCENARIO[[#Headers],[19-jun]]) -> 1.6927179e+09 | EK4: =SUMIFS('INGRESOSXDIA-HABIL'!$L$4:$L$25,'INGRESOSXDIA-HABIL'!$K$4:$K$25,ESCENARIO[[#Headers],[20-jun]]) -> 0 | EL4: =SUMIFS('INGRESOSXDIA-HABIL'!$L$4:$L$25,'INGRESOSXDIA-HABIL'!$K$4:$K$25,ESCENARIO[[#Headers],[21-jun]]) -> 0 | EM4: =SUMIFS('INGRESOSXDIA-HABIL'!$L$4:$L$25,'INGRESOSXDIA-HABIL'!$K$4:$K$25,ESCENARIO[[#Headers],[22-jun]]) -> 2.7638764e+09 | EN4: =SUMIFS('INGRESOSXDIA-HABIL'!$L$4:$L$25,'INGRESOSXDIA-HABIL'!$K$4:$K$25,ESCENARIO[[#Headers],[23-jun]]) -> 2.8639342e+09 | EO4: =SUMIFS('INGRESOSXDIA-HABIL'!$L$4:$L$25,'INGRESOSXDIA-HABIL'!$K$4:$K$25,ESCENARIO[[#Headers],[24-jun]]) -> 1.611677e+09 | EP4: =SUMIFS('INGRESOSXDIA-HABIL'!$L$4:$L$25,'INGRESOSXDIA-HABIL'!$K$4:$K$25,ESCENARIO[[#Headers],[25-jun]]) -> 3.0615361e+09 | EQ4: =SUMIFS('INGRESOSXDIA-HABIL'!$L$4:$L$25,'INGRESOSXDIA-HABIL'!$K$4:$K$25,ESCENARIO[[#Headers],[26-jun]]) -> 1.2511681e+09 | ER4: =SUMIFS('INGRESOSXDIA-HABIL'!$L$4:$L$25,'INGRESOSXDIA-HABIL'!$K$4:$K$25,ESCENARIO[[#Headers],[27-jun]]) -> 0 | ES4: =SUMIFS('INGRESOSXDIA-HABIL'!$L$4:$L$25,'INGRESOSXDIA-HABIL'!$K$4:$K$25,ESCENARIO[[#Headers],[28-jun]]) -> 0 | ET4: =SUMIFS('INGRESOSXDIA-HABIL'!$L$4:$L$25,'INGRESOSXDIA-HABIL'!$K$4:$K$25,ESCENARIO[[#Headers],[29-jun]]) -> 1.7282392e+09 | EU4: =SUMIFS('INGRESOSXDIA-HABIL'!$L$4:$L$25,'INGRESOSXDIA-HABIL'!$K$4:$K$25,ESCENARIO[[#Headers],[30-jun]]) -> 1.744645e+09 | EV4: =SUMIFS('INGRESOSXDIA-HABIL'!$N$4:$N$25,'INGRESOSXDIA-HABIL'!$M$4:$M$25,ESCENARIO[[#Headers],[01-jul]]) -> 6.8415136e+08 | EW4: =SUMIFS('INGRESOSXDIA-HABIL'!$N$4:$N$25,'INGRESOSXDIA-HABIL'!$M$4:$M$25,ESCENARIO[[#Headers],[02-jul]]) -> 9.333347e+08 | EX4: =SUMIFS('INGRESOSXDIA-HABIL'!$N$4:$N$25,'INGRESOSXDIA-HABIL'!$M$4:$M$25,ESCENARIO[[#Headers],[03-jul]]) -> 5.3166465e+08 | EY4: =SUMIFS('INGRESOSXDIA-HABIL'!$N$4:$N$25,'INGRESOSXDIA-HABIL'!$M$4:$M$25,ESCENARIO[[#Headers],[04-jul]]) -> 0 | EZ4: =SUMIFS('INGRESOSXDIA-HABIL'!$N$4:$N$25,'INGRESOSXDIA-HABIL'!$M$4:$M$25,ESCENARIO[[#Headers],[05-jul]]) -> 0 | FA4: =SUMIFS('INGRESOSXDIA-HABIL'!$N$4:$N$25,'INGRESOSXDIA-HABIL'!$M$4:$M$25,ESCENARIO[[#Headers],[06-jul]]) -> 6.715404e+08 | FB4: =SUMIFS('INGRESOSXDIA-HABIL'!$N$4:$N$25,'INGRESOSXDIA-HABIL'!$M$4:$M$25,ESCENARIO[[#Headers],[07-jul]]) -> 8.721463e+08 | FC4: =SUMIFS('INGRESOSXDIA-HABIL'!$N$4:$N$25,'INGRESOSXDIA-HABIL'!$M$4:$M$25,ESCENARIO[[#Headers],[08-jul]]) -> 1.5216446e+09 | FD4: =SUMIFS('INGRESOSXDIA-HABIL'!$N$4:$N$25,'INGRESOSXDIA-HABIL'!$M$4:$M$25,ESCENARIO[[#Headers],[09-jul]]) -> 0 | FE4: =SUMIFS('INGRESOSXDIA-HABIL'!$N$4:$N$25,'INGRESOSXDIA-HABIL'!$M$4:$M$25,ESCENARIO[[#Headers],[10-jul]]) -> 0 | FF4: =SUMIFS('INGRESOSXDIA-HABIL'!$N$4:$N$25,'INGRESOSXDIA-HABIL'!$M$4:$M$25,ESCENARIO[[#Headers],[11-jul]]) -> 0 | FG4: =SUMIFS('INGRESOSXDIA-HABIL'!$N$4:$N$25,'INGRESOSXDIA-HABIL'!$M$4:$M$25,ESCENARIO[[#Headers],[12-jul]]) -> 0 | FH4: =SUMIFS('INGRESOSXDIA-HABIL'!$N$4:$N$25,'INGRESOSXDIA-HABIL'!$M$4:$M$25,ESCENARIO[[#Headers],[13-jul]]) -> 7.7400292e+09 | FI4: =SUMIFS('INGRESOSXDIA-HABIL'!$N$4:$N$25,'INGRESOSXDIA-HABIL'!$M$4:$M$25,ESCENARIO[[#Headers],[14-jul]]) -> 1.4991512e+09 | FJ4: =SUMIFS('INGRESOSXDIA-HABIL'!$N$4:$N$25,'INGRESOSXDIA-HABIL'!$M$4:$M$25,ESCENARIO[[#Headers],[15-jul]]) -> 1.0055778e+09 | FK4: =SUMIFS('INGRESOSXDIA-HABIL'!$N$4:$N$25,'INGRESOSXDIA-HABIL'!$M$4:$M$25,ESCENARIO[[#Headers],[16-jul]]) -> 2.8278601e+09 | FL4: =SUMIFS('INGRESOSXDIA-HABIL'!$N$4:$N$25,'INGRESOSXDIA-HABIL'!$M$4:$M$25,ESCENARIO[[#Headers],[17-jul]]) -> 2.5850575e+09 | FM4: =SUMIFS('INGRESOSXDIA-HABIL'!$N$4:$N$25,'INGRESOSXDIA-HABIL'!$M$4:$M$25,ESCENARIO[[#Headers],[18-jul]]) -> 0 | FN4: =SUMIFS('INGRESOSXDIA-HABIL'!$N$4:$N$25,'INGRESOSXDIA-HABIL'!$M$4:$M$25,ESCENARIO[[#Headers],[19-jul]]) -> 0 | FO4: =SUMIFS('INGRESOSXDIA-HABIL'!$N$4:$N$25,'INGRESOSXDIA-HABIL'!$M$4:$M$25,ESCENARIO[[#Headers],[20-jul]]) -> 1.378148e+09 | FP4: =SUMIFS('INGRESOSXDIA-HABIL'!$N$4:$N$25,'INGRESOSXDIA-HABIL'!$M$4:$M$25,ESCENARIO[[#Headers],[21-jul]]) -> 1.6983601e+09 | FQ4: =SUMIFS('INGRESOSXDIA-HABIL'!$N$4:$N$25,'INGRESOSXDIA-HABIL'!$M$4:$M$25,ESCENARIO[[#Headers],[22-jul]]) -> 2.773089e+09 | FR4: =SUMIFS('INGRESOSXDIA-HABIL'!$N$4:$N$25,'INGRESOSXDIA-HABIL'!$M$4:$M$25,ESCENARIO[[#Headers],[23-jul]]) -> 2.8734803e+09 | FS4: =SUMIFS('INGRESOSXDIA-HABIL'!$N$4:$N$25,'INGRESOSXDIA-HABIL'!$M$4:$M$25,ESCENARIO[[#Headers],[24-jul]]) -> 1.617049e+09 | FT4: =SUMIFS('INGRESOSXDIA-HABIL'!$N$4:$N$25,'INGRESOSXDIA-HABIL'!$M$4:$M$25,ESCENARIO[[#Headers],[25-jul]]) -> 0 | FU4: =SUMIFS('INGRESOSXDIA-HABIL'!$N$4:$N$25,'INGRESOSXDIA-HABIL'!$M$4:$M$25,ESCENARIO[[#Headers],[26-jul]]) -> 0 | FV4: =SUMIFS('INGRESOSXDIA-HABIL'!$N$4:$N$25,'INGRESOSXDIA-HABIL'!$M$4:$M$25,ESCENARIO[[#Headers],[27-jul]]) -> 3.0717408e+09 | FW4: =SUMIFS('INGRESOSXDIA-HABIL'!$N$4:$N$25,'INGRESOSXDIA-HABIL'!$M$4:$M$25,ESCENARIO[[#Headers],[28-jul]]) -> 1.2553385e+09 | FX4: =SUMIFS('INGRESOSXDIA-HABIL'!$N$4:$N$25,'INGRESOSXDIA-HABIL'!$M$4:$M$25,ESCENARIO[[#Headers],[29-jul]]) -> 1.7339997e+09 | FY4: =SUMIFS('INGRESOSXDIA-HABIL'!$N$4:$N$25,'INGRESOSXDIA-HABIL'!$M$4:$M$25,ESCENARIO[[#Headers],[30-jul]]) -> 5.8195235e+08 | FZ4: =SUMIFS('INGRESOSXDIA-HABIL'!$N$4:$N$25,'INGRESOSXDIA-HABIL'!$M$4:$M$25,ESCENARIO[[#Headers],[31-jul]]) -> 1.1685079e+09 | GA4: =SUMIFS('INGRESOSXDIA-HABIL'!$P$4:$P$25,'INGRESOSXDIA-HABIL'!$O$4:$O$25,ESCENARIO[[#Headers],[01-ago]]) -> 0 | GB4: =SUMIFS('INGRESOSXDIA-HABIL'!$P$4:$P$25,'INGRESOSXDIA-HABIL'!$O$4:$O$25,ESCENARIO[[#Headers],[02-ago]]) -> 0 | GC4: =SUMIFS('INGRESOSXDIA-HABIL'!$P$4:$P$25,'INGRESOSXDIA-HABIL'!$O$4:$O$25,ESCENARIO[[#Headers],[03-ago]]) -> 6.9230868e+08 | GD4: =SUMIFS('INGRESOSXDIA-HABIL'!$P$4:$P$25,'INGRESOSXDIA-HABIL'!$O$4:$O$25,ESCENARIO[[#Headers],[04-ago]]) -> 9.444631e+08 | GE4: =SUMIFS('INGRESOSXDIA-HABIL'!$P$4:$P$25,'INGRESOSXDIA-HABIL'!$O$4:$O$25,ESCENARIO[[#Headers],[05-ago]]) -> 5.3800383e+08 | GF4: =SUMIFS('INGRESOSXDIA-HABIL'!$P$4:$P$25,'INGRESOSXDIA-HABIL'!$O$4:$O$25,ESCENARIO[[#Headers],[06-ago]]) -> 6.7954736e+08 | GG4: =SUMIFS('INGRESOSXDIA-HABIL'!$P$4:$P$25,'INGRESOSXDIA-HABIL'!$O$4:$O$25,ESCENARIO[[#Headers],[07-ago]]) -> 8.8254514e+08 | GH4: =SUMIFS('INGRESOSXDIA-HABIL'!$P$4:$P$25,'INGRESOSXDIA-HABIL'!$O$4:$O$25,ESCENARIO[[#Headers],[08-ago]]) -> 0 | GI4: =SUMIFS('INGRESOSXDIA-HABIL'!$P$4:$P$25,'INGRESOSXDIA-HABIL'!$O$4:$O$25,ESCENARIO[[#Headers],[09-ago]]) -> 0 | GJ4: =SUMIFS('INGRESOSXDIA-HABIL'!$P$4:$P$25,'INGRESOSXDIA-HABIL'!$O$4:$O$25,ESCENARIO[[#Headers],[10-ago]]) -> 1.5397876e+09 | GK4: =SUMIFS('INGRESOSXDIA-HABIL'!$P$4:$P$25,'INGRESOSXDIA-HABIL'!$O$4:$O$25,ESCENARIO[[#Headers],[11-ago]]) -> 7.8323156e+09 | GL4: =SUMIFS('INGRESOSXDIA-HABIL'!$P$4:$P$25,'INGRESOSXDIA-HABIL'!$O$4:$O$25,ESCENARIO[[#Headers],[12-ago]]) -> 1.517026e+09 | GM4: =SUMIFS('INGRESOSXDIA-HABIL'!$P$4:$P$25,'INGRESOSXDIA-HABIL'!$O$4:$O$25,ESCENARIO[[#Headers],[13-ago]]) -> 1.0175676e+09 | GN4: =SUMIFS('INGRESOSXDIA-HABIL'!$P$4:$P$25,'INGRESOSXDIA-HABIL'!$O$4:$O$25,ESCENARIO[[#Headers],[14-ago]]) -> 2.8615774e+09 | GO4: =SUMIFS('INGRESOSXDIA-HABIL'!$P$4:$P$25,'INGRESOSXDIA-HABIL'!$O$4:$O$25,ESCENARIO[[#Headers],[15-ago]]) -> 0 | GP4: =SUMIFS('INGRESOSXDIA-HABIL'!$P$4:$P$25,'INGRESOSXDIA-HABIL'!$O$4:$O$25,ESCENARIO[[#Headers],[16-ago]]) -> 0 | GQ4: =SUMIFS('INGRESOSXDIA-HABIL'!$P$4:$P$25,'INGRESOSXDIA-HABIL'!$O$4:$O$25,ESCENARIO[[#Headers],[17-ago]]) -> 2.6158798e+09 | GR4: =SUMIFS('INGRESOSXDIA-HABIL'!$P$4:$P$25,'INGRESOSXDIA-HABIL'!$O$4:$O$25,ESCENARIO[[#Headers],[18-ago]]) -> 1.39458e+09 | GS4: =SUMIFS('INGRESOSXDIA-HABIL'!$P$4:$P$25,'INGRESOSXDIA-HABIL'!$O$4:$O$25,ESCENARIO[[#Headers],[19-ago]]) -> 1.7186101e+09 | GT4: =SUMIFS('INGRESOSXDIA-HABIL'!$P$4:$P$25,'INGRESOSXDIA-HABIL'!$O$4:$O$25,ESCENARIO[[#Headers],[20-ago]]) -> 2.8061533e+09 | GU4: =SUMIFS('INGRESOSXDIA-HABIL'!$P$4:$P$25,'INGRESOSXDIA-HABIL'!$O$4:$O$25,ESCENARIO[[#Headers],[21-ago]]) -> 2.9077416e+09 | GV4: =SUMIFS('INGRESOSXDIA-HABIL'!$P$4:$P$25,'INGRESOSXDIA-HABIL'!$O$4:$O$25,ESCENARIO[[#Headers],[22-ago]]) -> 0 | GW4: =SUMIFS('INGRESOSXDIA-HABIL'!$P$4:$P$25,'INGRESOSXDIA-HABIL'!$O$4:$O$25,ESCENARIO[[#Headers],[23-ago]]) -> 0 | GX4: =SUMIFS('INGRESOSXDIA-HABIL'!$P$4:$P$25,'INGRESOSXDIA-HABIL'!$O$4:$O$25,ESCENARIO[[#Headers],[24-ago]]) -> 1.6363296e+09 | GY4: =SUMIFS('INGRESOSXDIA-HABIL'!$P$4:$P$25,'INGRESOSXDIA-HABIL'!$O$4:$O$25,ESCENARIO[[#Headers],[25-ago]]) -> 3.108366e+09 | GZ4: =SUMIFS('INGRESOSXDIA-HABIL'!$P$4:$P$25,'INGRESOSXDIA-HABIL'!$O$4:$O$25,ESCENARIO[[#Headers],[26-ago]]) -> 1.2703062e+09 | HA4: =SUMIFS('INGRESOSXDIA-HABIL'!$P$4:$P$25,'INGRESOSXDIA-HABIL'!$O$4:$O$25,ESCENARIO[[#Headers],[27-ago]]) -> 1.7546747e+09 | HB4: =SUMIFS('INGRESOSXDIA-HABIL'!$P$4:$P$25,'INGRESOSXDIA-HABIL'!$O$4:$O$25,ESCENARIO[[#Headers],[28-ago]]) -> 5.8889113e+08 | HC4: =SUMIFS('INGRESOSXDIA-HABIL'!$P$4:$P$25,'INGRESOSXDIA-HABIL'!$O$4:$O$25,ESCENARIO[[#Headers],[29-ago]]) -> 0 | HD4: =SUMIFS('INGRESOSXDIA-HABIL'!$P$4:$P$25,'INGRESOSXDIA-HABIL'!$O$4:$O$25,ESCENARIO[[#Headers],[30-ago]]) -> 0 | HE4: =SUMIFS('INGRESOSXDIA-HABIL'!$P$4:$P$25,'INGRESOSXDIA-HABIL'!$O$4:$O$25,ESCENARIO[[#Headers],[31-ago]]) -> 1.1824404e+09 | HF4: =SUMIFS('INGRESOSXDIA-HABIL'!$R$4:$R$25,'INGRESOSXDIA-HABIL'!$Q$4:$Q$25,ESCENARIO[[#Headers],[01-sep]]) -> 0 | HG4: =SUMIFS('INGRESOSXDIA-HABIL'!$R$4:$R$25,'INGRESOSXDIA-HABIL'!$Q$4:$Q$25,ESCENARIO[[#Headers],[02-sep]]) -> 7.1543221e+08 | HH4: =SUMIFS('INGRESOSXDIA-HABIL'!$R$4:$R$25,'INGRESOSXDIA-HABIL'!$Q$4:$Q$25,ESCENARIO[[#Headers],[03-sep]]) -> 9.7600874e+08 | HI4: =SUMIFS('INGRESOSXDIA-HABIL'!$R$4:$R$25,'INGRESOSXDIA-HABIL'!$Q$4:$Q$25,ESCENARIO[[#Headers],[04-sep]]) -> 5.5597348e+08 | HJ4: =SUMIFS('INGRESOSXDIA-HABIL'!$R$4:$R$25,'INGRESOSXDIA-HABIL'!$Q$4:$Q$25,ESCENARIO[[#Headers],[05-sep]]) -> 0 | HK4: =SUMIFS('INGRESOSXDIA-HABIL'!$R$4:$R$25,'INGRESOSXDIA-HABIL'!$Q$4:$Q$25,ESCENARIO[[#Headers],[06-sep]]) -> 0 | HL4: =SUMIFS('INGRESOSXDIA-HABIL'!$R$4:$R$25,'INGRESOSXDIA-HABIL'!$Q$4:$Q$25,ESCENARIO[[#Headers],[07-sep]]) -> 7.0224465e+08 | HM4: =SUMIFS('INGRESOSXDIA-HABIL'!$R$4:$R$25,'INGRESOSXDIA-HABIL'!$Q$4:$Q$25,ESCENARIO[[#Headers],[08-sep]]) -> 9.1202268e+08 | HN4: =SUMIFS('INGRESOSXDIA-HABIL'!$R$4:$R$25,'INGRESOSXDIA-HABIL'!$Q$4:$Q$25,ESCENARIO[[#Headers],[09-sep]]) -> 1.5912175e+09 | HO4: =SUMIFS('INGRESOSXDIA-HABIL'!$R$4:$R$25,'INGRESOSXDIA-HABIL'!$Q$4:$Q$25,ESCENARIO[[#Headers],[10-sep]]) -> 8.0939197e+09 | HP4: =SUMIFS('INGRESOSXDIA-HABIL'!$R$4:$R$25,'INGRESOSXDIA-HABIL'!$Q$4:$Q$25,ESCENARIO[[#Headers],[11-sep]]) -> 1.5676956e+09 | HQ4: =SUMIFS('INGRESOSXDIA-HABIL'!$R$4:$R$25,'INGRESOSXDIA-HABIL'!$Q$4:$Q$25,ESCENARIO[[#Headers],[12-sep]]) -> 0 | HR4: =SUMIFS('INGRESOSXDIA-HABIL'!$R$4:$R$25,'INGRESOSXDIA-HABIL'!$Q$4:$Q$25,ESCENARIO[[#Headers],[13-sep]]) -> 0 | HS4: =SUMIFS('INGRESOSXDIA-HABIL'!$R$4:$R$25,'INGRESOSXDIA-HABIL'!$Q$4:$Q$25,ESCENARIO[[#Headers],[14-sep]]) -> 1.051555e+09 | HT4: =SUMIFS('INGRESOSXDIA-HABIL'!$R$4:$R$25,'INGRESOSXDIA-HABIL'!$Q$4:$Q$25,ESCENARIO[[#Headers],[15-sep]]) -> 2.9571558e+09 | HU4: =SUMIFS('INGRESOSXDIA-HABIL'!$R$4:$R$25,'INGRESOSXDIA-HABIL'!$Q$4:$Q$25,ESCENARIO[[#Headers],[16-sep]]) -> 2.7032518e+09 | HV4: =SUMIFS('INGRESOSXDIA-HABIL'!$R$4:$R$25,'INGRESOSXDIA-HABIL'!$Q$4:$Q$25,ESCENARIO[[#Headers],[17-sep]]) -> 1.4411599e+09 | HW4: =SUMIFS('INGRESOSXDIA-HABIL'!$R$4:$R$25,'INGRESOSXDIA-HABIL'!$Q$4:$Q$25,ESCENARIO[[#Headers],[18-sep]]) -> 1.7760127e+09 | HX4: =SUMIFS('INGRESOSXDIA-HABIL'!$R$4:$R$25,'INGRESOSXDIA-HABIL'!$Q$4:$Q$25,ESCENARIO[[#Headers],[19-sep]]) -> 0 | HY4: =SUMIFS('INGRESOSXDIA-HABIL'!$R$4:$R$25,'INGRESOSXDIA-HABIL'!$Q$4:$Q$25,ESCENARIO[[#Headers],[20-sep]]) -> 0 | HZ4: =SUMIFS('INGRESOSXDIA-HABIL'!$R$4:$R$25,'INGRESOSXDIA-HABIL'!$Q$4:$Q$25,ESCENARIO[[#Headers],[21-sep]]) -> 2.8998805e+09 | IA4: =SUMIFS('INGRESOSXDIA-HABIL'!$R$4:$R$25,'INGRESOSXDIA-HABIL'!$Q$4:$Q$25,ESCENARIO[[#Headers],[22-sep]]) -> 3.0048619e+09 | IB4: =SUMIFS('INGRESOSXDIA-HABIL'!$R$4:$R$25,'INGRESOSXDIA-HABIL'!$Q$4:$Q$25,ESCENARIO[[#Headers],[23-sep]]) -> 1.6909839e+09 | IC4: =SUMIFS('INGRESOSXDIA-HABIL'!$R$4:$R$25,'INGRESOSXDIA-HABIL'!$Q$4:$Q$25,ESCENARIO[[#Headers],[24-sep]]) -> 3.2121873e+09 | ID4: =SUMIFS('INGRESOSXDIA-HABIL'!$R$4:$R$25,'INGRESOSXDIA-HABIL'!$Q$4:$Q$25,ESCENARIO[[#Headers],[25-sep]]) -> 1.3127352e+09 | IE4: =SUMIFS('INGRESOSXDIA-HABIL'!$R$4:$R$25,'INGRESOSXDIA-HABIL'!$Q$4:$Q$25,ESCENARIO[[#Headers],[26-sep]]) -> 0 | IF4: =SUMIFS('INGRESOSXDIA-HABIL'!$R$4:$R$25,'INGRESOSXDIA-HABIL'!$Q$4:$Q$25,ESCENARIO[[#Headers],[27-sep]]) -> 0 | IG4: =SUMIFS('INGRESOSXDIA-HABIL'!$R$4:$R$25,'INGRESOSXDIA-HABIL'!$Q$4:$Q$25,ESCENARIO[[#Headers],[28-sep]]) -> 1.8132819e+09 | IH4: =SUMIFS('INGRESOSXDIA-HABIL'!$R$4:$R$25,'INGRESOSXDIA-HABIL'!$Q$4:$Q$25,ESCENARIO[[#Headers],[29-sep]]) -> 6.0856044e+08 | II4: =SUMIFS('INGRESOSXDIA-HABIL'!$R$4:$R$25,'INGRESOSXDIA-HABIL'!$Q$4:$Q$25,ESCENARIO[[#Headers],[30-sep]]) -> 1.2219346e+09 | IJ4: =SUMIFS('INGRESOSXDIA-HABIL'!$T$4:$T$25,'INGRESOSXDIA-HABIL'!$S$4:$S$25,ESCENARIO[[#Headers],[01-oct]]) -> 7.4531187e+08 | IK4: =SUMIFS('INGRESOSXDIA-HABIL'!$T$4:$T$25,'INGRESOSXDIA-HABIL'!$S$4:$S$25,ESCENARIO[[#Headers],[02-oct]]) -> 1.0167712e+09 | IL4: =SUMIFS('INGRESOSXDIA-HABIL'!$T$4:$T$25,'INGRESOSXDIA-HABIL'!$S$4:$S$25,ESCENARIO[[#Headers],[03-oct]]) -> 0 | IM4: =SUMIFS('INGRESOSXDIA-HABIL'!$T$4:$T$25,'INGRESOSXDIA-HABIL'!$S$4:$S$25,ESCENARIO[[#Headers],[04-oct]]) -> 0 | IN4: =SUMIFS('INGRESOSXDIA-HABIL'!$T$4:$T$25,'INGRESOSXDIA-HABIL'!$S$4:$S$25,ESCENARIO[[#Headers],[05-oct]]) -> 5.7919343e+08 | IO4: =SUMIFS('INGRESOSXDIA-HABIL'!$T$4:$T$25,'INGRESOSXDIA-HABIL'!$S$4:$S$25,ESCENARIO[[#Headers],[06-oct]]) -> 7.3157354e+08 | IP4: =SUMIFS('INGRESOSXDIA-HABIL'!$T$4:$T$25,'INGRESOSXDIA-HABIL'!$S$4:$S$25,ESCENARIO[[#Headers],[07-oct]]) -> 9.5011284e+08 | IQ4: =SUMIFS('INGRESOSXDIA-HABIL'!$T$4:$T$25,'INGRESOSXDIA-HABIL'!$S$4:$S$25,ESCENARIO[[#Headers],[08-oct]]) -> 1.6576738e+09 | IR4: =SUMIFS('INGRESOSXDIA-HABIL'!$T$4:$T$25,'INGRESOSXDIA-HABIL'!$S$4:$S$25,ESCENARIO[[#Headers],[09-oct]]) -> 8.4319581e+09 | IS4: =SUMIFS('INGRESOSXDIA-HABIL'!$T$4:$T$25,'INGRESOSXDIA-HABIL'!$S$4:$S$25,ESCENARIO[[#Headers],[10-oct]]) -> 0 | IT4: =SUMIFS('INGRESOSXDIA-HABIL'!$T$4:$T$25,'INGRESOSXDIA-HABIL'!$S$4:$S$25,ESCENARIO[[#Headers],[11-oct]]) -> 0 | IU4: =SUMIFS('INGRESOSXDIA-HABIL'!$T$4:$T$25,'INGRESOSXDIA-HABIL'!$S$4:$S$25,ESCENARIO[[#Headers],[12-oct]]) -> 0 | IV4: =SUMIFS('INGRESOSXDIA-HABIL'!$T$4:$T$25,'INGRESOSXDIA-HABIL'!$S$4:$S$25,ESCENARIO[[#Headers],[13-oct]]) -> 1.6331696e+09 | IW4: =SUMIFS('INGRESOSXDIA-HABIL'!$T$4:$T$25,'INGRESOSXDIA-HABIL'!$S$4:$S$25,ESCENARIO[[#Headers],[14-oct]]) -> 1.0954726e+09 | IX4: =SUMIFS('INGRESOSXDIA-HABIL'!$T$4:$T$25,'INGRESOSXDIA-HABIL'!$S$4:$S$25,ESCENARIO[[#Headers],[15-oct]]) -> 3.0806599e+09 | IY4: =SUMIFS('INGRESOSXDIA-HABIL'!$T$4:$T$25,'INGRESOSXDIA-HABIL'!$S$4:$S$25,ESCENARIO[[#Headers],[16-oct]]) -> 2.8161517e+09 | IZ4: =SUMIFS('INGRESOSXDIA-HABIL'!$T$4:$T$25,'INGRESOSXDIA-HABIL'!$S$4:$S$25,ESCENARIO[[#Headers],[17-oct]]) -> 0 | JA4: =SUMIFS('INGRESOSXDIA-HABIL'!$T$4:$T$25,'INGRESOSXDIA-HABIL'!$S$4:$S$25,ESCENARIO[[#Headers],[18-oct]]) -> 0 | JB4: =SUMIFS('INGRESOSXDIA-HABIL'!$T$4:$T$25,'INGRESOSXDIA-HABIL'!$S$4:$S$25,ESCENARIO[[#Headers],[19-oct]]) -> 1.5013492e+09 | JC4: =SUMIFS('INGRESOSXDIA-HABIL'!$T$4:$T$25,'INGRESOSXDIA-HABIL'!$S$4:$S$25,ESCENARIO[[#Headers],[20-oct]]) -> 1.8501869e+09 | JD4: =SUMIFS('INGRESOSXDIA-HABIL'!$T$4:$T$25,'INGRESOSXDIA-HABIL'!$S$4:$S$25,ESCENARIO[[#Headers],[21-oct]]) -> 3.0209925e+09 | JE4: =SUMIFS('INGRESOSXDIA-HABIL'!$T$4:$T$25,'INGRESOSXDIA-HABIL'!$S$4:$S$25,ESCENARIO[[#Headers],[22-oct]]) -> 3.1303584e+09 | JF4: =SUMIFS('INGRESOSXDIA-HABIL'!$T$4:$T$25,'INGRESOSXDIA-HABIL'!$S$4:$S$25,ESCENARIO[[#Headers],[23-oct]]) -> 1.761607e+09 | JG4: =SUMIFS('INGRESOSXDIA-HABIL'!$T$4:$T$25,'INGRESOSXDIA-HABIL'!$S$4:$S$25,ESCENARIO[[#Headers],[24-oct]]) -> 0 | JH4: =SUMIFS('INGRESOSXDIA-HABIL'!$T$4:$T$25,'INGRESOSXDIA-HABIL'!$S$4:$S$25,ESCENARIO[[#Headers],[25-oct]]) -> 0 | JI4: =SUMIFS('INGRESOSXDIA-HABIL'!$T$4:$T$25,'INGRESOSXDIA-HABIL'!$S$4:$S$25,ESCENARIO[[#Headers],[26-oct]]) -> 3.3463426e+09 | JJ4: =SUMIFS('INGRESOSXDIA-HABIL'!$T$4:$T$25,'INGRESOSXDIA-HABIL'!$S$4:$S$25,ESCENARIO[[#Headers],[27-oct]]) -> 1.3675609e+09 | JK4: =SUMIFS('INGRESOSXDIA-HABIL'!$T$4:$T$25,'INGRESOSXDIA-HABIL'!$S$4:$S$25,ESCENARIO[[#Headers],[28-oct]]) -> 1.8890127e+09 | JL4: =SUMIFS('INGRESOSXDIA-HABIL'!$T$4:$T$25,'INGRESOSXDIA-HABIL'!$S$4:$S$25,ESCENARIO[[#Headers],[29-oct]]) -> 6.3397666e+08 | JM4: =SUMIFS('INGRESOSXDIA-HABIL'!$T$4:$T$25,'INGRESOSXDIA-HABIL'!$S$4:$S$25,ESCENARIO[[#Headers],[30-oct]]) -> 1.2729681e+09 | JN4: =SUMIFS('INGRESOSXDIA-HABIL'!$T$4:$T$25,'INGRESOSXDIA-HABIL'!$S$4:$S$25,ESCENARIO[[#Headers],[31-oct]]) -> 0 | JO4: =SUMIFS('INGRESOSXDIA-HABIL'!$V$4:$V$23,'INGRESOSXDIA-HABIL'!$U$4:$U$23,ESCENARIO[[#Headers],[01-nov]]) -> 0 | JP4: =SUMIFS('INGRESOSXDIA-HABIL'!$V$4:$V$23,'INGRESOSXDIA-HABIL'!$U$4:$U$23,ESCENARIO[[#Headers],[02-nov]]) -> 7.5625571e+08 | JQ4: =SUMIFS('INGRESOSXDIA-HABIL'!$V$4:$V$23,'INGRESOSXDIA-HABIL'!$U$4:$U$23,ESCENARIO[[#Headers],[03-nov]]) -> 1.0317011e+09 | JR4: =SUMIFS('INGRESOSXDIA-HABIL'!$V$4:$V$23,'INGRESOSXDIA-HABIL'!$U$4:$U$23,ESCENARIO[[#Headers],[04-nov]]) -> 5.8769805e+08 | JS4: =SUMIFS('INGRESOSXDIA-HABIL'!$V$4:$V$23,'INGRESOSXDIA-HABIL'!$U$4:$U$23,ESCENARIO[[#Headers],[05-nov]]) -> 7.4231565e+08 | JT4: =SUMIFS('INGRESOSXDIA-HABIL'!$V$4:$V$23,'INGRESOSXDIA-HABIL'!$U$4:$U$23,ESCENARIO[[#Headers],[06-nov]]) -> 9.6406388e+08 | JU4: =SUMIFS('INGRESOSXDIA-HABIL'!$V$4:$V$23,'INGRESOSXDIA-HABIL'!$U$4:$U$23,ESCENARIO[[#Headers],[07-nov]]) -> 0 | JV4: =SUMIFS('INGRESOSXDIA-HABIL'!$V$4:$V$23,'INGRESOSXDIA-HABIL'!$U$4:$U$23,ESCENARIO[[#Headers],[08-nov]]) -> 0 | JW4: =SUMIFS('INGRESOSXDIA-HABIL'!$V$4:$V$23,'INGRESOSXDIA-HABIL'!$U$4:$U$23,ESCENARIO[[#Headers],[09-nov]]) -> 1.6820144e+09 | JX4: =SUMIFS('INGRESOSXDIA-HABIL'!$V$4:$V$23,'INGRESOSXDIA-HABIL'!$U$4:$U$23,ESCENARIO[[#Headers],[10-nov]]) -> 8.5557693e+09 | JY4: =SUMIFS('INGRESOSXDIA-HABIL'!$V$4:$V$23,'INGRESOSXDIA-HABIL'!$U$4:$U$23,ESCENARIO[[#Headers],[11-nov]]) -> 1.6571504e+09 | JZ4: =SUMIFS('INGRESOSXDIA-HABIL'!$V$4:$V$23,'INGRESOSXDIA-HABIL'!$U$4:$U$23,ESCENARIO[[#Headers],[12-nov]]) -> 1.1115581e+09 | KA4: =SUMIFS('INGRESOSXDIA-HABIL'!$V$4:$V$23,'INGRESOSXDIA-HABIL'!$U$4:$U$23,ESCENARIO[[#Headers],[13-nov]]) -> 3.125895e+09 | KB4: =SUMIFS('INGRESOSXDIA-HABIL'!$V$4:$V$23,'INGRESOSXDIA-HABIL'!$U$4:$U$23,ESCENARIO[[#Headers],[14-nov]]) -> 0 | KC4: =SUMIFS('INGRESOSXDIA-HABIL'!$V$4:$V$23,'INGRESOSXDIA-HABIL'!$U$4:$U$23,ESCENARIO[[#Headers],[15-nov]]) -> 0 | KD4: =SUMIFS('INGRESOSXDIA-HABIL'!$V$4:$V$23,'INGRESOSXDIA-HABIL'!$U$4:$U$23,ESCENARIO[[#Headers],[16-nov]]) -> 2.8575028e+09 | KE4: =SUMIFS('INGRESOSXDIA-HABIL'!$V$4:$V$23,'INGRESOSXDIA-HABIL'!$U$4:$U$23,ESCENARIO[[#Headers],[17-nov]]) -> 1.5233943e+09 | KF4: =SUMIFS('INGRESOSXDIA-HABIL'!$V$4:$V$23,'INGRESOSXDIA-HABIL'!$U$4:$U$23,ESCENARIO[[#Headers],[18-nov]]) -> 1.8773543e+09 | KG4: =SUMIFS('INGRESOSXDIA-HABIL'!$V$4:$V$23,'INGRESOSXDIA-HABIL'!$U$4:$U$23,ESCENARIO[[#Headers],[19-nov]]) -> 3.0653514e+09 | KH4: =SUMIFS('INGRESOSXDIA-HABIL'!$V$4:$V$23,'INGRESOSXDIA-HABIL'!$U$4:$U$23,ESCENARIO[[#Headers],[20-nov]]) -> 3.1763232e+09 | KI4: =SUMIFS('INGRESOSXDIA-HABIL'!$V$4:$V$23,'INGRESOSXDIA-HABIL'!$U$4:$U$23,ESCENARIO[[#Headers],[21-nov]]) -> 0 | KJ4: =SUMIFS('INGRESOSXDIA-HABIL'!$V$4:$V$23,'INGRESOSXDIA-HABIL'!$U$4:$U$23,ESCENARIO[[#Headers],[22-nov]]) -> 0 | KK4: =SUMIFS('INGRESOSXDIA-HABIL'!$V$4:$V$23,'INGRESOSXDIA-HABIL'!$U$4:$U$23,ESCENARIO[[#Headers],[23-nov]]) -> 0 | KL4: =SUMIFS('INGRESOSXDIA-HABIL'!$V$4:$V$23,'INGRESOSXDIA-HABIL'!$U$4:$U$23,ESCENARIO[[#Headers],[24-nov]]) -> 1.7874737e+09 | KM4: =SUMIFS('INGRESOSXDIA-HABIL'!$V$4:$V$23,'INGRESOSXDIA-HABIL'!$U$4:$U$23,ESCENARIO[[#Headers],[25-nov]]) -> 3.3954789e+09 | KN4: =SUMIFS('INGRESOSXDIA-HABIL'!$V$4:$V$23,'INGRESOSXDIA-HABIL'!$U$4:$U$23,ESCENARIO[[#Headers],[26-nov]]) -> 1.3876416e+09 | KO4: =SUMIFS('INGRESOSXDIA-HABIL'!$V$4:$V$23,'INGRESOSXDIA-HABIL'!$U$4:$U$23,ESCENARIO[[#Headers],[27-nov]]) -> 1.9167501e+09 | KP4: =SUMIFS('INGRESOSXDIA-HABIL'!$V$4:$V$23,'INGRESOSXDIA-HABIL'!$U$4:$U$23,ESCENARIO[[#Headers],[28-nov]]) -> 0 | KQ4: =SUMIFS('INGRESOSXDIA-HABIL'!$V$4:$V$23,'INGRESOSXDIA-HABIL'!$U$4:$U$23,ESCENARIO[[#Headers],[29-nov]]) -> 0 | KR4: =SUMIFS('INGRESOSXDIA-HABIL'!$V$4:$V$23,'INGRESOSXDIA-HABIL'!$U$4:$U$23,ESCENARIO[[#Headers],[30-nov]]) -> 1.9349455e+09 | KS4: =SUMIFS('INGRESOSXDIA-HABIL'!$X$4:$X$25,'INGRESOSXDIA-HABIL'!$W$4:$W$25,ESCENARIO[[#Headers],[01-dic]]) -> 7.9140486e+08 | KT4: =SUMIFS('INGRESOSXDIA-HABIL'!$X$4:$X$25,'INGRESOSXDIA-HABIL'!$W$4:$W$25,ESCENARIO[[#Headers],[02-dic]]) -> 1.0796523e+09 | KU4: =SUMIFS('INGRESOSXDIA-HABIL'!$X$4:$X$25,'INGRESOSXDIA-HABIL'!$W$4:$W$25,ESCENARIO[[#Headers],[03-dic]]) -> 6.1501301e+08 | KV4: =SUMIFS('INGRESOSXDIA-HABIL'!$X$4:$X$25,'INGRESOSXDIA-HABIL'!$W$4:$W$25,ESCENARIO[[#Headers],[04-dic]]) -> 7.768169e+08 | KW4: =SUMIFS('INGRESOSXDIA-HABIL'!$X$4:$X$25,'INGRESOSXDIA-HABIL'!$W$4:$W$25,ESCENARIO[[#Headers],[05-dic]]) -> 0 | KX4: =SUMIFS('INGRESOSXDIA-HABIL'!$X$4:$X$25,'INGRESOSXDIA-HABIL'!$W$4:$W$25,ESCENARIO[[#Headers],[06-dic]]) -> 0 | KY4: =SUMIFS('INGRESOSXDIA-HABIL'!$X$4:$X$25,'INGRESOSXDIA-HABIL'!$W$4:$W$25,ESCENARIO[[#Headers],[07-dic]]) -> 0 | KZ4: =SUMIFS('INGRESOSXDIA-HABIL'!$X$4:$X$25,'INGRESOSXDIA-HABIL'!$W$4:$W$25,ESCENARIO[[#Headers],[08-dic]]) -> 0 | LA4: =SUMIFS('INGRESOSXDIA-HABIL'!$X$4:$X$25,'INGRESOSXDIA-HABIL'!$W$4:$W$25,ESCENARIO[[#Headers],[09-dic]]) -> 1.0088715e+09 | LB4: =SUMIFS('INGRESOSXDIA-HABIL'!$X$4:$X$25,'INGRESOSXDIA-HABIL'!$W$4:$W$25,ESCENARIO[[#Headers],[10-dic]]) -> 1.7601909e+09 | LC4: =SUMIFS('INGRESOSXDIA-HABIL'!$X$4:$X$25,'INGRESOSXDIA-HABIL'!$W$4:$W$25,ESCENARIO[[#Headers],[11-dic]]) -> 8.9534232e+09 | LD4: =SUMIFS('INGRESOSXDIA-HABIL'!$X$4:$X$25,'INGRESOSXDIA-HABIL'!$W$4:$W$25,ESCENARIO[[#Headers],[12-dic]]) -> 0 | LE4: =SUMIFS('INGRESOSXDIA-HABIL'!$X$4:$X$25,'INGRESOSXDIA-HABIL'!$W$4:$W$25,ESCENARIO[[#Headers],[13-dic]]) -> 0 | LF4: =SUMIFS('INGRESOSXDIA-HABIL'!$X$4:$X$25,'INGRESOSXDIA-HABIL'!$W$4:$W$25,ESCENARIO[[#Headers],[14-dic]]) -> 1.7341712e+09 | LG4: =SUMIFS('INGRESOSXDIA-HABIL'!$X$4:$X$25,'INGRESOSXDIA-HABIL'!$W$4:$W$25,ESCENARIO[[#Headers],[15-dic]]) -> 1.1632209e+09 | LH4: =SUMIFS('INGRESOSXDIA-HABIL'!$X$4:$X$25,'INGRESOSXDIA-HABIL'!$W$4:$W$25,ESCENARIO[[#Headers],[16-dic]]) -> 3.2711799e+09 | LI4: =SUMIFS('INGRESOSXDIA-HABIL'!$X$4:$X$25,'INGRESOSXDIA-HABIL'!$W$4:$W$25,ESCENARIO[[#Headers],[17-dic]]) -> 2.9903135e+09 | LJ4: =SUMIFS('INGRESOSXDIA-HABIL'!$X$4:$X$25,'INGRESOSXDIA-HABIL'!$W$4:$W$25,ESCENARIO[[#Headers],[18-dic]]) -> 1.5941984e+09 | LK4: =SUMIFS('INGRESOSXDIA-HABIL'!$X$4:$X$25,'INGRESOSXDIA-HABIL'!$W$4:$W$25,ESCENARIO[[#Headers],[19-dic]]) -> 0 | LL4: =SUMIFS('INGRESOSXDIA-HABIL'!$X$4:$X$25,'INGRESOSXDIA-HABIL'!$W$4:$W$25,ESCENARIO[[#Headers],[20-dic]]) -> 0 | LM4: =SUMIFS('INGRESOSXDIA-HABIL'!$X$4:$X$25,'INGRESOSXDIA-HABIL'!$W$4:$W$25,ESCENARIO[[#Headers],[21-dic]]) -> 1.9646097e+09 | LN4: =SUMIFS('INGRESOSXDIA-HABIL'!$X$4:$X$25,'INGRESOSXDIA-HABIL'!$W$4:$W$25,ESCENARIO[[#Headers],[22-dic]]) -> 3.2078224e+09 | LO4: =SUMIFS('INGRESOSXDIA-HABIL'!$X$4:$X$25,'INGRESOSXDIA-HABIL'!$W$4:$W$25,ESCENARIO[[#Headers],[23-dic]]) -> 3.323952e+09 | LP4: =SUMIFS('INGRESOSXDIA-HABIL'!$X$4:$X$25,'INGRESOSXDIA-HABIL'!$W$4:$W$25,ESCENARIO[[#Headers],[24-dic]]) -> 1.8705517e+09 | LQ4: =SUMIFS('INGRESOSXDIA-HABIL'!$X$4:$X$25,'INGRESOSXDIA-HABIL'!$W$4:$W$25,ESCENARIO[[#Headers],[25-dic]]) -> 0 | LR4: =SUMIFS('INGRESOSXDIA-HABIL'!$X$4:$X$25,'INGRESOSXDIA-HABIL'!$W$4:$W$25,ESCENARIO[[#Headers],[26-dic]]) -> 0 | LS4: =SUMIFS('INGRESOSXDIA-HABIL'!$X$4:$X$25,'INGRESOSXDIA-HABIL'!$W$4:$W$25,ESCENARIO[[#Headers],[27-dic]]) -> 0 | LT4: =SUMIFS('INGRESOSXDIA-HABIL'!$X$4:$X$25,'INGRESOSXDIA-HABIL'!$W$4:$W$25,ESCENARIO[[#Headers],[28-dic]]) -> 3.5532935e+09 | LU4: =SUMIFS('INGRESOSXDIA-HABIL'!$X$4:$X$25,'INGRESOSXDIA-HABIL'!$W$4:$W$25,ESCENARIO[[#Headers],[29-dic]]) -> 1.4521362e+09 | LV4: =SUMIFS('INGRESOSXDIA-HABIL'!$X$4:$X$25,'INGRESOSXDIA-HABIL'!$W$4:$W$25,ESCENARIO[[#Headers],[30-dic]]) -> 2.0058366e+09 | LW4: =SUMIFS('INGRESOSXDIA-HABIL'!$X$4:$X$25,'INGRESOSXDIA-HABIL'!$W$4:$W$25,ESCENARIO[[#Headers],[31-dic]]) -> 2.0248776e+09 | LX4: =SUM(ESCENARIO[[#This Row],[01-mar]:[31-dic]]) -> 4.0394539e+11
A5: RESCATE DE FCI | B5: =IF(B2>B3,0,B2-B3) -> 0 | C5: =IF(C2>C3,0,C2-C3) -> -235000000 | D5: =IF(D2>D3,0,D2-D3) -> -8.0705818e+08 | E5: =IF(E2>E3,0,E2-E3) -> 0 | F5: =IF(F2>F3,0,F2-F3) -> 0 | G5: =IF(G2>G3,0,G2-G3) -> 0 | H5: =IF(H2>H3,0,H2-H3) -> 0 | I5: =IF(I2>I3,0,I2-I3) -> 0 | ... LW5: =IF(LW2>LW3,0,LW2-LW3) -> 0 | LX5: =SUM(ESCENARIO[[#This Row],[01-mar]:[31-dic]]) -> -2.8562925e+11
A6: INTERES DIARIO (0.0967%) | C6: =+B7*0.0967% -> 2297689.7 | D6: =+C7*0.0967% -> 2070444.7 | E6: =+D7*0.0967% -> 1290019.4 | F6: =+E7*0.0967% -> 2134991.9 | G6: =+F7*0.0967% -> 2615892.1 | H6: =+G7*0.0967% -> 3223312.3 | I6: =+H7*0.0967% -> 4012184.2 | J6: =+I7*0.0967% -> 4012184.2 | ... LW6: =+LV7*0.0967% -> 71093235 | LX6: =SUM(ESCENARIO[[#This Row],[01-mar]:[31-dic]]) -> 1.0734236e+10
